Workbook
Name Acs: Constants!$B$33
Name Adc: Loop_Modeling!$B$38
Name Adc_ea: Loop_Modeling!$B$62
Name ADC_VINmin: Variable_Management!$B$160
Name CCOMP: Variable_Management!$B$225
Name CCOMP_Calc: Variable_Management!$B$224
Name CCOMP_calc_CCM: Variable_Management!$B$189
Name CCOMP_CALC_DCM: Variable_Management!$B$215
Name CHF: Variable_Management!$B$227
Name CHF_calc: Variable_Management!$B$226
Name CHF_CALC_CCM: Variable_Management!$B$190
Name CHF_CALC_DCM: Variable_Management!$B$216
Name Comp_calc_CCM: Variable_Management!$B$189
Name Cout: Variable_Management!$B$110
Name Cout_min: Variable_Management!$B$108
Name D_limit_max: Constants!$B$18
Name D_limit_min: Constants!$B$16
Name D_limit_nom: Constants!$B$17
Name DC_DCM_max: Variable_Management!$B$39
Name Dc_max_IC: Variable_Management!$B$23
Name Dc_max_ideal: Variable_Management!$A$22
Name DC_rip: Variable_Management!$B$32
Name Dc_rip_max: Variable_Management!$B$31
Name Dc_VIN_max: Variable_Management!$B$71
Name Dc_VIN_min: Variable_Management!$B$55
Name Dc_VIN_nom: Variable_Management!$B$63
Name DC_VIN_var_DCM: Loop_Modeling!$B$70
Name EFF_est: Variable_Management!$B$16
Name Eff_vs_IOUT: Plot_Management_Eff!$C$3
Name fcross: Variable_Management!$B$220
Name fcross_est: Variable_Management!$B$219
Name fp_ea_est: Variable_Management!$B$182
Name Fsw: Variable_Management!$B$10
Name fz_ea_est: Variable_Management!$B$181
Name fz_rhp: Variable_Management!$B$169
Name Gcomp: Constants!$B$32
Name Gea_mid_calc: Variable_Management!#REF!
Name gfs: Variable_Management!$B$243
Name gm_ea: Constants!$B$37
Name Gplant_fc_dB: Loop_Modeling!$AD$7
Name IIN_33: Variable_Management!$B$35
Name IL_avg_VIN_max: Variable_Management!$B$73
Name IL_avg_VIN_min: Variable_Management!$B$57
Name IL_avg_VIN_nom: Variable_Management!$B$65
Name IL_pk: Variable_Management!$B$94
Name IL_pk_max: Variable_Management!$B$95
Name ILp_VINmax: Variable_Management!$B$75
Name ILp_VINmin: Variable_Management!$B$59
Name ILp_VINnom: Variable_Management!$B$67
Name ILrip: Variable_Management!$B$30
Name ILrip_VINmax: Variable_Management!$B$74
Name ILrip_VINmin: Variable_Management!$B$58
Name ILrip_VINnom: Variable_Management!$B$66
Name IOUT: Variable_Management!$B$13
Name IOUT_VAR: Loop_Modeling!$B$17
Name Ipk_margin: Variable_Management!$B$78
Name Ipk_selected: Variable_Management!$B$80
Name IQ: Constants!$B$58
Name IRMS_COUT: Variable_Management!$B$109
Name Isl: Constants!$B$26

Sheet Design Converter
E1: LM5123 BOOST Controller Design Tool
A3: ABOUT | F3: =Input Box | O3: TERMS OF USE
O5: Rev 0.2 | P5: December-2021
A6: Step 1: Design Specifications
G7: Minimum Input Supply Voltage , VSUPPLY(min) | H7: 10 | I7: V
G8: Typical Input Supply Voltage, VSUPPLY(typ) | H8: 3 | I8: V
G9: Maximum Input Supply Voltage , VSUPPLY(max) | H9: 16 | I9: V
G10: Output Target Voltage, VLOAD | H10: 50 | I10: V
G11: Maximum Output Current , ILOAD | H11: 4.5 | I11: A
G12: Light load operation switching mode | H12: DEM
G13: Free Running Switching Frequency, FSW | H13: 440 | I13: kHz
G14: Free running Oscillator Set Resistor, RT | H14: =RT/1000 -> 49.272273 | I14: kΩ
G15: Output Power, POUT | H15: =POUT -> 225 | I15: W
G16: Boost Converter Duty Cycle Limit of LM5123 at VSUPPLY(MIN) | H16: =Dc_max_IC*100 -> 88 | I16: %
G17: Ideal Duty Cycle at VSUPPLY(MIN) | H17: =Variable_Management!B22*100 -> 80 | I17: %
A19: Step 2: Filter Inductor
G20: Switching mode at VSUPPLY(min) | H20: =CHOOSE(Variable_Management!B25, "DCM","CCM") -> CCM
G21: =CHOOSE(Variable_Management!B25,"Maximum duty cycle at the minimum supply voltage","Desired Maximum Inductor Current Ripple Ratio") -> Desired Maximum Inductor Current Ripple Ratio | H21: 20 | I21: %
G22: Recommended Inductance (LM_CALC) | H22: =CHOOSE(Variable_Management!B25,Variable_Management!B45*10^9,Variable_Management!B45*10^6) -> 8.7919192 | I22: =CHOOSE(Variable_Management!B25,"nH","uH") -> uH
G23: User Selection. Inductance, (LM) | H23: 10 | I23: =CHOOSE(Variable_Management!B25,"nH","uH") -> uH
G24: Max Inductor DCR, RDCR | H24: 7.5 | I24: mΩ
G25: Peak inductor current, ILPK | H25: =ILp_VINmin -> 23.409091 | I25: A
A27: Step 3: Current Sense Resistor Selection
G28: Peak Current Limit Margin | H28: 30 | I28: %
G29: Selected Peak Current limit(ILPK_select) | H29: =Ipk_selected -> 31.971292 | I29: A
G30: Recommended current sense Resistor (RS) | H30: =Variable_Management!B87*1000 -> 1.8766836 | I30: mΩ
G31: Selected current sense Resistor (RS) | H31: 2 | I31: mΩ
G32: Actual inductor peak current limit | H32: =IL_pk_max -> 30 | I32: A
A34: Step 4: Output Capacitor Selection
G35: Desired load step ripple voltage (ΔvOUT) | H35: 500 | I35: mV
G36: Minimum output capacitance | H36: =Cout_min*10^6 -> 506.25 | I36: uF
G37: Selected Output Capacitance (COUT) | H37: 470 | I37: uF
G38: Equivalent COUT ESR (RESR) | H38: 35 | I38: mΩ
A40: Step 6: Soft-Start Capacitor Selection
G41: Suggested minimum soft-start capacitor (CSS_MIN) | H41: =Variable_Management!B117*(10^9) -> 104.44444 | I41: nF
G42: Desied soft-start time at minimum input voltage (TSS) | H42: 10 | I42: ms
G43: Calculated soft-start capacitor (CSS) | H43: =Variable_Management!B119*(10^9) -> 250 | I43: nF
A45: Step 5: UVLO Resistor Divider Selection
G46: Desired voltage On (VUVLO_ON) | H46: 8 | I46: V
G47: Desired voltage OFF (VUVLO_OFF) | H47: 7 | I47: V
...

Sheet Variable_Management
A1: EXCEL Variables Names/Calculations
B2: Input from user =
B3: Output = | F3: Base Calculations of | G3: Spec conditions | H3: Normal
B4: Constant
A5: Variable Name | B5: Value | C5: STD Units | E5: Notes | J5: Iteration | K5: Flag
A6: Step 1: Operational Specs
A7: VIN_min | B7: ='Design Converter'!H7 -> 10 | C7: V | E7: Minimum input voltage
A8: VIN_nom | B8: ='Design Converter'!H8 -> 3 | C8: V | E8: Nominal input voltage | K8: =IF(VIN_min<VIN_min,1,IF(VIN_nom>VIN_max,1,0)) -> 0
A9: VIN_max | B9: ='Design Converter'!H9 -> 16 | C9: V | E9: Maximum input voltage
A10: Fsw | B10: ='Design Converter'!H13*1000 -> 440000 | C10: Hz | E10: Switching frequnecy
A11: RT | B11: =((2.21*10^10)/Fsw)-955 -> 49272.273 | C11: Ω | E11: Oscillator Set resistor. Based on the datasheet equation
A12: VOUT | B12: ='Design Converter'!H10 -> 50 | C12: V | E12: Target Output Voltage
A13: IOUT | B13: ='Design Converter'!H11 -> 4.5 | C13: A | E13: Maximum Output current
A14: ROUT | B14: =VOUT/IOUT -> 11.111111 | C14: Ω | E14: Minimum load resistance
A15: POUT | B15: =VOUT*IOUT -> 225 | C15: W | E15: Total output power
A16: EFF_est | B16: 1 | E16: Estimated efficiency. Assuming 100% simplify the calculations
A17: Np | B17: 1 | E17: number of phases in operation (For the LM5123 only one phase is possilbe with out external circuts)
A19: VOUT_range | B19: =IF(VOUT<=15,1,2) -> 2 | E19: Sets the feedback divider. Unique to the LM5123 topology (1 = low voltage <=15V, 2 = high voltage >15V)
A20: SW_mode | B20: =IF('Design Converter'!H12="FPWM",3,IF('Design Converter'!H12="DEM",2,1)) -> 2 | E20: selected switching mode (1 = SKIP, 2 = DEM, 3 =FPWM) Will change the effieciency calculations accordingly
A22: Dc_max_ideal | B22: =1-VIN_min*EFF_est/VOUT -> 0.8 | E22: Maximum duty cycle at the minimum input voltage. Includes estimated efficiency for margin
A23: Dc_max_IC | B23: =Constants!B20-0.02 -> 0.88 | E23: Maximum IC duty cycle. Based on the forced off time and frequency. Give the equation about 2% margin to allow for losses in the controller
A25: DCM_Flag | B25: =IF(B22>Dc_max_IC,1,2) -> 2 | E25: 1: DCM operation required at VINmin to achieve the step-up ratio. | K25: =IF(B25=1,1,0) -> 0
E26: 2: CCM operation can achieve step-up ratio with out violating the maximum duty cycle
A28: Step 2: Filter Inductor | E28: =AND((1-(VIN_max/VOUT))<Dc_rip_max,(1-(VIN_min/VOUT))<Dc_rip_max) -> FALSE
A29: CCM Operation calculations
A30: ILrip | B30: ='Design Converter'!H21/100 -> 0.2 | E30: Selected indutor ripple ratio. Will be changed later to a standard value just to keep things simple
A31: Dc_rip_max | B31: 0.33 | C31: % | E31: Peak ripple ratio: Boost this happens at 33%
A32: DC_rip | B32: =IF(AND((1-(VIN_max/VOUT))<Dc_rip_max,(1-(VIN_min/VOUT))>=Dc_rip_max),Dc_rip_max,IF((1-(VIN_max/VOUT))>Dc_rip_max,(1-(VIN_max/VOUT)),IF((1-(VIN_min/VOUT))<Dc_rip_max,(1-(VIN_min/VOUT)),0.33))) -> 0.68
A33: VIN_33 | B33: =VOUT*(1-DC_rip) -> 16 | C33: V | E33: Input voltage at maximum ripple duty cycle. If maximum input voltage Dc is >.33 this value will be used
A35: IIN_33 | B35: =(VOUT*IOUT)/(VIN_33) -> 14.0625 | C35: A | E35: Input current at maximum ripple duty cycle
A36: Lopt_2 | B36: =(VIN_33*DC_rip)/(IIN_33*ILrip*Fsw) -> 8.7919192e-06 | C36: H | E36: This value used to make the selection for CCM calculations
A38: DCM Operation calculations
A39: DC_DCM_max | B39: ='Design Converter'!H21/100 -> 0.2 | E39: Maximum duty cycle for DCM operation. 70% is a good starting point. Could be related to the switching frequency
A40: L_DCM_DC | B40: =((DC_DCM_max^2)*(VIN_min^2))/(2*IOUT*VOUT*Fsw-2*IOUT*VIN_min*Fsw) -> 2.5252525e-08 | C40: H | E40: Select DCM duty cycle to be 70%. This will keep the ripple current fairly low and allow for efficiency drops.
A41: M_L_DCM | B41: 0.2 | E41: Margin to allow for inductor ripple current to be greater than the average input current
A42: L_DCM_M | B42: =(1-M_L_DCM)*((VIN_min^2)*(1-(VIN_min/VOUT)))/(2*IOUT*VOUT*Fsw) -> 3.2323232e-07 | C42: H | E42: Inductor value that ensures the ripple current is larger than the average input current
A43: L_DCM | B43: =MIN(B40,B42) -> 2.5252525e-08 | C43: H | E43: Select the lowest of the two inductor value calculations
A45: Lm_calc | B45: =IF(B25=1,B43,Lopt_2) -> 8.7919192e-06 | E45: If DCM is required (high step-up ratio) output L_DCM. Otherwise output the CCM inductor value
A47: Lm | B47: =CHOOSE(B25,'Design Converter'!H23*10^-9,'Design Converter'!H23*10^-6) -> 1e-05 | C47: H | E47: Selected filter inductor
A48: Rdcr | B48: ='Design Converter'!H24*10^-3 -> 0.0075 | C48: Ω | E48: Filter inductor DCR
...

Sheet Eff_vs_IOUT
A1: EXCEL Variables Names/Calculations
R5: Operation Variables | V5: Duty Cycle | Y5: Inductor | AE5: Low-Side MOSFET | AJ5: High-Side MOSFET Losses | AP5: Other Losses | AU5: Total Losses
R6: VOUT | S6: IOUT | T6: VIN | U6: IIN | V6: DCM/CCM | W6: DC | X6: DC_off | Y6: dIL | Z6: ILPEAK | AA6: ILRMS | AB6: PLac (W) | AC6: PL_DCR (W) | AD6: PL_tot (W) | AE6: ISWAVG (A) | AF6: ISWRMS | AG6: PQ_COND (W) | AH6: PQ_SW (W) | AI6: PQ_tot (W) | AJ6: IDAVG (A) | AK6: IHSRMS | AL6: PD_COND (W) | AM6: PD_SW (W) | AN6: Dead Time losses | AO6: PHS_tot (W) | AP6: PRCS (W) | AQ6: PL_DCR (W) | AR6: PL_CORE (W) | AS6: PG_drv (W) | AT6: PIQ (W) | AU6: PTOTAL (W) | AV6: POUT (W) | AW6: Eff
Q7: 0 | R7: =VOUT -> 50 | S7: =Q7*$O$12 -> 0 | T7: =VIN_var -> 3 | U7: =(R7*S7)/(T7*EFF_est) -> 0 | V7: =IF(Variable_Management!$B$20=3,2,IF((S7*R7/T7)<((T7*(1-(T7/R7)))/(2*Lm*Fsw)),1,2)) -> 1 | W7: =CHOOSE(V7,SQRT((2*S7*Lm*Fsw*(R7-T7))/((T7)^2)),1-(T7/R7)) -> 0 | X7: =CHOOSE(V7,(Lm*Z7*Fsw)/(R7-T7),1-W7) -> 0 | Y7: =(T7*W7)/(Lm*Fsw) -> 0 | Z7: =CHOOSE(V7,Y7,U7+(0.5*Y7)) -> 0 | AA7: =CHOOSE(V7,Z7*SQRT((W7+X7)/3),SQRT((U7^2)+((Y7^2)/12))) -> 0 | AB7: 0 | AC7: =(AA7^2)*Rdcr -> 0 | AD7: =AB7+AC7 -> 0 | AE7: =U7*W7 -> 0 | AF7: =CHOOSE(V7,Z7*SQRT(W7/3),SQRT(W7*((Z7^2)+((Y7^2)/3)-(Z7*Y7)))) -> 0 | AG7: =(AF7^2)*RDS_on -> 0 | AH7: =((R7*U7)/2)*Fsw*(tr_sw+tf_sw) -> 0 | AI7: =AG7+AH7 -> 0 | AJ7: =X7*U7 -> 0 | AK7: =CHOOSE(V7,Z7*SQRT(X7/3),SQRT(X7*((Z7^2)+((Y7^2)/3)-(Y7*Z7)))) -> 0 | AL7: =(AK7^2)*RDS_on_HS -> 0 | AM7: =CHOOSE(V7,0,(R7+Vd_rect)*Qrr*Fsw) -> 0 | AN7: =Vd_rect*t_dead*Fsw*Z7 -> 0 | AO7: =AL7+AM7+AN7 -> 0 | AP7: =(AA7^2)*R_cs -> 0 | AQ7: =Rdcr*AA7^2 -> 0 | AR7: =ABS(7.759*10^-3*Fsw^0.9458*(0.00787*Y7)^2.304) -> 0 | AS7: =(Qg_tot+Qg_tot_HS)*Vcc*Fsw -> 0.044 | AT7: =IQ*T7 -> 9.9e-06 | AU7: =AP7+AO7+AI7+AD7+AS7+AT7+AQ7+AR7 -> 0.0440099 | AV7: =R7*S7 -> 0 | AW7: =(AV7/(AV7+AU7))*100 -> 0
M8: =Fsw -> 440000 | Q8: 1 | R8: =VOUT -> 50 | S8: =Q8*$O$12 -> 0.03 | T8: =VIN_var -> 3 | U8: =(R8*S8)/(T8*EFF_est) -> 0.5 | V8: =IF(Variable_Management!$B$20=3,2,IF((S8*R8/T8)<((T8*(1-(T8/R8)))/(2*Lm*Fsw)),1,2)) -> 2 | W8: =CHOOSE(V8,SQRT((2*S8*Lm*Fsw*(R8-T8))/((T8)^2)),1-(T8/R8)) -> 0.94 | X8: =CHOOSE(V8,(Lm*Z8*Fsw)/(R8-T8),1-W8) -> 0.06 | Y8: =(T8*W8)/(Lm*Fsw) -> 0.64090909 | Z8: =CHOOSE(V8,Y8,U8+(0.5*Y8)) -> 0.82045455 | AA8: =CHOOSE(V8,Z8*SQRT((W8+X8)/3),SQRT((U8^2)+((Y8^2)/12))) -> 0.5331326 | AB8: 0 | AC8: =(AA8^2)*Rdcr -> 0.0021317278 | AD8: =AB8+AC8 -> 0.0021317278 | AE8: =U8*W8 -> 0.47 | AF8: =CHOOSE(V8,Z8*SQRT(W8/3),SQRT(W8*((Z8^2)+((Y8^2)/3)-(Z8*Y8)))) -> 0.51689124 | AG8: =(AF8^2)*RDS_on -> 0.0099389676 | AH8: =((R8*U8)/2)*Fsw*(tr_sw+tf_sw) -> 0.10434517 | AI8: =AG8+AH8 -> 0.11428413 | AJ8: =X8*U8 -> 0.03 | AK8: =CHOOSE(V8,Z8*SQRT(X8/3),SQRT(X8*((Z8^2)+((Y8^2)/3)-(Y8*Z8)))) -> 0.13059028 | AL8: =(AK8^2)*RDS_on_HS -> 0.00015007364 | AM8: =CHOOSE(V8,(R8+Vd_rect)*Qrr*Fsw,(R8+Vd_rect)*Qrr*Fsw) -> 0.737616 | AN8: =Vd_rect*t_dead*Fsw*Z8 -> 0.005776 | AO8: =AL8+AM8+AN8 -> 0.74354207 | AP8: =(AA8^2)*R_cs -> 0.00056846074 | AQ8: =Rdcr*AA8^2 -> 0.0021317278 | AR8: =ABS(7.759*10^-3*Fsw^0.9458*(0.00787*Y8)^2.304) -> 0.0086013784 | AS8: =(Qg_tot+Qg_tot_HS)*Vcc*Fsw -> 0.044 | AT8: =IQ*T8 -> 9.9e-06 | AU8: =AP8+AO8+AI8+AD8+AS8+AT8+AQ8+AR8 -> 0.9152694 | AV8: =R8*S8 -> 1.5 | AW8: =(AV8/(AV8+AU8))*100 -> 62.104873
N9: VIN_VAR | O9: =VIN_var -> 3 | P9: V | Q9: 2 | R9: =VOUT -> 50 | S9: =Q9*$O$12 -> 0.06 | T9: =VIN_var -> 3 | U9: =(R9*S9)/(T9*EFF_est) -> 1 | V9: =IF(Variable_Management!$B$20=3,2,IF((S9*R9/T9)<((T9*(1-(T9/R9)))/(2*Lm*Fsw)),1,2)) -> 2 | W9: =CHOOSE(V9,SQRT((2*S9*Lm*Fsw*(R9-T9))/((T9)^2)),1-(T9/R9)) -> 0.94 | X9: =CHOOSE(V9,(Lm*Z9*Fsw)/(R9-T9),1-W9) -> 0.06 | Y9: =(T9*W9)/(Lm*Fsw) -> 0.64090909 | Z9: =CHOOSE(V9,Y9,U9+(0.5*Y9)) -> 1.3204545 | AA9: =CHOOSE(V9,Z9*SQRT((W9+X9)/3),SQRT((U9^2)+((Y9^2)/12))) -> 1.0169712 | AB9: 0 | AC9: =(AA9^2)*Rdcr -> 0.0077567278 | AD9: =AB9+AC9 -> 0.0077567278 | AE9: =U9*W9 -> 0.94 | AF9: =CHOOSE(V9,Z9*SQRT(W9/3),SQRT(W9*((Z9^2)+((Y9^2)/3)-(Z9*Y9)))) -> 0.98599014 | AG9: =(AF9^2)*RDS_on -> 0.036164968 | AH9: =((R9*U9)/2)*Fsw*(tr_sw+tf_sw) -> 0.20869033 | AI9: =AG9+AH9 -> 0.2448553 | AJ9: =X9*U9 -> 0.06 | AK9: =CHOOSE(V9,Z9*SQRT(X9/3),SQRT(X9*((Z9^2)+((Y9^2)/3)-(Y9*Z9)))) -> 0.24910605 | AL9: =(AK9^2)*RDS_on_HS -> 0.00054607364 | AM9: =CHOOSE(V9,(R9+Vd_rect)*Qrr*Fsw,(R9+Vd_rect)*Qrr*Fsw) -> 0.737616 | AN9: =Vd_rect*t_dead*Fsw*Z9 -> 0.009296 | AO9: =AL9+AM9+AN9 -> 0.74745807 | AP9: =(AA9^2)*R_cs -> 0.0020684607 | AQ9: =Rdcr*AA9^2 -> 0.0077567278 | AR9: =ABS(7.759*10^-3*Fsw^0.9458*(0.00787*Y9)^2.304) -> 0.0086013784 | AS9: =(Qg_tot+Qg_tot_HS)*Vcc*Fsw -> 0.044 | AT9: =IQ*T9 -> 9.9e-06 | AU9: =AP9+AO9+AI9+AD9+AS9+AT9+AQ9+AR9 -> 1.0625066 | AV9: =R9*S9 -> 3 | AW9: =(AV9/(AV9+AU9))*100 -> 73.846034
Q10: 3 | R10: =VOUT -> 50 | S10: =Q10*$O$12 -> 0.09 | T10: =VIN_var -> 3 | U10: =(R10*S10)/(T10*EFF_est) -> 1.5 | V10: =IF(Variable_Management!$B$20=3,2,IF((S10*R10/T10)<((T10*(1-(T10/R10)))/(2*Lm*Fsw)),1,2)) -> 2 | W10: =CHOOSE(V10,SQRT((2*S10*Lm*Fsw*(R10-T10))/((T10)^2)),1-(T10/R10)) -> 0.94 | X10: =CHOOSE(V10,(Lm*Z10*Fsw)/(R10-T10),1-W10) -> 0.06 | Y10: =(T10*W10)/(Lm*Fsw) -> 0.64090909 | Z10: =CHOOSE(V10,Y10,U10+(0.5*Y10)) -> 1.8204545 | AA10: =CHOOSE(V10,Z10*SQRT((W10+X10)/3),SQRT((U10^2)+((Y10^2)/12))) -> 1.5113671 | AB10: 0 | AC10: =(AA10^2)*Rdcr -> 0.017131728 | AD10: =AB10+AC10 -> 0.017131728 | AE10: =U10*W10 -> 1.41 | AF10: =CHOOSE(V10,Z10*SQRT(W10/3),SQRT(W10*((Z10^2)+((Y10^2)/3)-(Z10*Y10)))) -> 1.4653247 | AG10: =(AF10^2)*RDS_on -> 0.079874968 | AH10: =((R10*U10)/2)*Fsw*(tr_sw+tf_sw) -> 0.3130355 | AI10: =AG10+AH10 -> 0.39291046 | AJ10: =X10*U10 -> 0.09 | AK10: =CHOOSE(V10,Z10*SQRT(X10/3),SQRT(X10*((Z10^2)+((Y10^2)/3)-(Y10*Z10)))) -> 0.37020781 | AL10: =(AK10^2)*RDS_on_HS -> 0.0012060736 | AM10: =CHOOSE(V10,(R10+Vd_rect)*Qrr*Fsw,(R10+Vd_rect)*Qrr*Fsw) -> 0.737616 | AN10: =Vd_rect*t_dead*Fsw*Z10 -> 0.012816 | AO10: =AL10+AM10+AN10 -> 0.75163807 | AP10: =(AA10^2)*R_cs -> 0.0045684607 | AQ10: =Rdcr*AA10^2 -> 0.017131728 | AR10: =ABS(7.759*10^-3*Fsw^0.9458*(0.00787*Y10)^2.304) -> 0.0086013784 | AS10: =(Qg_tot+Qg_tot_HS)*Vcc*Fsw -> 0.044 | AT10: =IQ*T10 -> 9.9e-06 | AU10: =AP10+AO10+AI10+AD10+AS10+AT10+AQ10+AR10 -> 1.2359917 | AV10: =R10*S10 -> 4.5 | AW10: =(AV10/(AV10+AU10))*100 -> 78.451996
N11: Steps | O11: 150 | Q11: 4 | R11: =VOUT -> 50 | S11: =Q11*$O$12 -> 0.12 | T11: =VIN_var -> 3 | U11: =(R11*S11)/(T11*EFF_est) -> 2 | V11: =IF(Variable_Management!$B$20=3,2,IF((S11*R11/T11)<((T11*(1-(T11/R11)))/(2*Lm*Fsw)),1,2)) -> 2 | W11: =CHOOSE(V11,SQRT((2*S11*Lm*Fsw*(R11-T11))/((T11)^2)),1-(T11/R11)) -> 0.94 | X11: =CHOOSE(V11,(Lm*Z11*Fsw)/(R11-T11),1-W11) -> 0.06 | Y11: =(T11*W11)/(Lm*Fsw) -> 0.64090909 | Z11: =CHOOSE(V11,Y11,U11+(0.5*Y11)) -> 2.3204545 | AA11: =CHOOSE(V11,Z11*SQRT((W11+X11)/3),SQRT((U11^2)+((Y11^2)/12))) -> 2.0085394 | AB11: 0 | AC11: =(AA11^2)*Rdcr -> 0.030256728 | AD11: =AB11+AC11 -> 0.030256728 | AE11: =U11*W11 -> 1.88 | AF11: =CHOOSE(V11,Z11*SQRT(W11/3),SQRT(W11*((Z11^2)+((Y11^2)/3)-(Z11*Y11)))) -> 1.9473512 | AG11: =(AF11^2)*RDS_on -> 0.14106897 | AH11: =((R11*U11)/2)*Fsw*(tr_sw+tf_sw) -> 0.41738066 | AI11: =AG11+AH11 -> 0.55844963 | AJ11: =X11*U11 -> 0.12 | AK11: =CHOOSE(V11,Z11*SQRT(X11/3),SQRT(X11*((Z11^2)+((Y11^2)/3)-(Y11*Z11)))) -> 0.49198966 | AL11: =(AK11^2)*RDS_on_HS -> 0.0021300736 | AM11: =CHOOSE(V11,(R11+Vd_rect)*Qrr*Fsw,(R11+Vd_rect)*Qrr*Fsw) -> 0.737616 | AN11: =Vd_rect*t_dead*Fsw*Z11 -> 0.016336 | AO11: =AL11+AM11+AN11 -> 0.75608207 | AP11: =(AA11^2)*R_cs -> 0.0080684607 | AQ11: =Rdcr*AA11^2 -> 0.030256728 | AR11: =ABS(7.759*10^-3*Fsw^0.9458*(0.00787*Y11)^2.304) -> 0.0086013784 | AS11: =(Qg_tot+Qg_tot_HS)*Vcc*Fsw -> 0.044 | AT11: =IQ*T11 -> 9.9e-06 | AU11: =AP11+AO11+AI11+AD11+AS11+AT11+AQ11+AR11 -> 1.4357249 | AV11: =R11*S11 -> 6 | AW11: =(AV11/(AV11+AU11))*100 -> 80.691527
N12: Step size | O12: =IOUT/(O11) -> 0.03 | Q12: 5 | R12: =VOUT -> 50 | S12: =Q12*$O$12 -> 0.15 | T12: =VIN_var -> 3 | U12: =(R12*S12)/(T12*EFF_est) -> 2.5 | V12: =IF(Variable_Management!$B$20=3,2,IF((S12*R12/T12)<((T12*(1-(T12/R12)))/(2*Lm*Fsw)),1,2)) -> 2 | W12: =CHOOSE(V12,SQRT((2*S12*Lm*Fsw*(R12-T12))/((T12)^2)),1-(T12/R12)) -> 0.94 | X12: =CHOOSE(V12,(Lm*Z12*Fsw)/(R12-T12),1-W12) -> 0.06 | Y12: =(T12*W12)/(Lm*Fsw) -> 0.64090909 | Z12: =CHOOSE(V12,Y12,U12+(0.5*Y12)) -> 2.8204545 | AA12: =CHOOSE(V12,Z12*SQRT((W12+X12)/3),SQRT((U12^2)+((Y12^2)/12))) -> 2.5068367 | AB12: 0 | AC12: =(AA12^2)*Rdcr -> 0.047131728 | AD12: =AB12+AC12 -> 0.047131728 | AE12: =U12*W12 -> 2.35 | AF12: =CHOOSE(V12,Z12*SQRT(W12/3),SQRT(W12*((Z12^2)+((Y12^2)/3)-(Z12*Y12)))) -> 2.4304684 | AG12: =(AF12^2)*RDS_on -> 0.21974697 | AH12: =((R12*U12)/2)*Fsw*(tr_sw+tf_sw) -> 0.52172583 | AI12: =AG12+AH12 -> 0.74147279 | AJ12: =X12*U12 -> 0.15 | AK12: =CHOOSE(V12,Z12*SQRT(X12/3),SQRT(X12*((Z12^2)+((Y12^2)/3)-(Y12*Z12)))) -> 0.61404708 | AL12: =(AK12^2)*RDS_on_HS -> 0.0033180736 | AM12: =CHOOSE(V12,(R12+Vd_rect)*Qrr*Fsw,(R12+Vd_rect)*Qrr*Fsw) -> 0.737616 | AN12: =Vd_rect*t_dead*Fsw*Z12 -> 0.019856 | AO12: =AL12+AM12+AN12 -> 0.76079007 | AP12: =(AA12^2)*R_cs -> 0.012568461 | AQ12: =Rdcr*AA12^2 -> 0.047131728 | AR12: =ABS(7.759*10^-3*Fsw^0.9458*(0.00787*Y12)^2.304) -> 0.0086013784 | AS12: =(Qg_tot+Qg_tot_HS)*Vcc*Fsw -> 0.044 | AT12: =IQ*T12 -> 9.9e-06 | AU12: =AP12+AO12+AI12+AD12+AS12+AT12+AQ12+AR12 -> 1.6617061 | AV12: =R12*S12 -> 7.5 | AW12: =(AV12/(AV12+AU12))*100 -> 81.862482
Q13: 6 | R13: =VOUT -> 50 | S13: =Q13*$O$12 -> 0.18 | T13: =VIN_var -> 3 | U13: =(R13*S13)/(T13*EFF_est) -> 3 | V13: =IF(Variable_Management!$B$20=3,2,IF((S13*R13/T13)<((T13*(1-(T13/R13)))/(2*Lm*Fsw)),1,2)) -> 2 | W13: =CHOOSE(V13,SQRT((2*S13*Lm*Fsw*(R13-T13))/((T13)^2)),1-(T13/R13)) -> 0.94 | X13: =CHOOSE(V13,(Lm*Z13*Fsw)/(R13-T13),1-W13) -> 0.06 | Y13: =(T13*W13)/(Lm*Fsw) -> 0.64090909 | Z13: =CHOOSE(V13,Y13,U13+(0.5*Y13)) -> 3.3204545 | AA13: =CHOOSE(V13,Z13*SQRT((W13+X13)/3),SQRT((U13^2)+((Y13^2)/12))) -> 3.0056996 | AB13: 0 | AC13: =(AA13^2)*Rdcr -> 0.067756728 | AD13: =AB13+AC13 -> 0.067756728 | AE13: =U13*W13 -> 2.82 | AF13: =CHOOSE(V13,Z13*SQRT(W13/3),SQRT(W13*((Z13^2)+((Y13^2)/3)-(Z13*Y13)))) -> 2.9141339 | AG13: =(AF13^2)*RDS_on -> 0.31590897 | AH13: =((R13*U13)/2)*Fsw*(tr_sw+tf_sw) -> 0.62607099 | AI13: =AG13+AH13 -> 0.94197996 | AJ13: =X13*U13 -> 0.18 | AK13: =CHOOSE(V13,Z13*SQRT(X13/3),SQRT(X13*((Z13^2)+((Y13^2)/3)-(Y13*Z13)))) -> 0.73624305 | AL13: =(AK13^2)*RDS_on_HS -> 0.0047700736 | AM13: =CHOOSE(V13,(R13+Vd_rect)*Qrr*Fsw,(R13+Vd_rect)*Qrr*Fsw) -> 0.737616 | AN13: =Vd_rect*t_dead*Fsw*Z13 -> 0.023376 | AO13: =AL13+AM13+AN13 -> 0.76576207 | AP13: =(AA13^2)*R_cs -> 0.018068461 | AQ13: =Rdcr*AA13^2 -> 0.067756728 | AR13: =ABS(7.759*10^-3*Fsw^0.9458*(0.00787*Y13)^2.304) -> 0.0086013784 | AS13: =(Qg_tot+Qg_tot_HS)*Vcc*Fsw -> 0.044 | AT13: =IQ*T13 -> 9.9e-06 | AU13: =AP13+AO13+AI13+AD13+AS13+AT13+AQ13+AR13 -> 1.9139352 | AV13: =R13*S13 -> 9 | AW13: =(AV13/(AV13+AU13))*100 -> 82.463381
Q14: 7 | R14: =VOUT -> 50 | S14: =Q14*$O$12 -> 0.21 | T14: =VIN_var -> 3 | U14: =(R14*S14)/(T14*EFF_est) -> 3.5 | V14: =IF(Variable_Management!$B$20=3,2,IF((S14*R14/T14)<((T14*(1-(T14/R14)))/(2*Lm*Fsw)),1,2)) -> 2 | W14: =CHOOSE(V14,SQRT((2*S14*Lm*Fsw*(R14-T14))/((T14)^2)),1-(T14/R14)) -> 0.94 | X14: =CHOOSE(V14,(Lm*Z14*Fsw)/(R14-T14),1-W14) -> 0.06 | Y14: =(T14*W14)/(Lm*Fsw) -> 0.64090909 | Z14: =CHOOSE(V14,Y14,U14+(0.5*Y14)) -> 3.8204545 | AA14: =CHOOSE(V14,Z14*SQRT((W14+X14)/3),SQRT((U14^2)+((Y14^2)/12))) -> 3.5048866 | AB14: 0 | AC14: =(AA14^2)*Rdcr -> 0.092131728 | AD14: =AB14+AC14 -> 0.092131728 | AE14: =U14*W14 -> 3.29 | AF14: =CHOOSE(V14,Z14*SQRT(W14/3),SQRT(W14*((Z14^2)+((Y14^2)/3)-(Z14*Y14)))) -> 3.3981137 | AG14: =(AF14^2)*RDS_on -> 0.42955497 | AH14: =((R14*U14)/2)*Fsw*(tr_sw+tf_sw) -> 0.73041616 | AI14: =AG14+AH14 -> 1.1599711 | AJ14: =X14*U14 -> 0.21 | AK14: =CHOOSE(V14,Z14*SQRT(X14/3),SQRT(X14*((Z14^2)+((Y14^2)/3)-(Y14*Z14)))) -> 0.85851839 | AL14: =(AK14^2)*RDS_on_HS -> 0.0064860736 | AM14: =CHOOSE(V14,(R14+Vd_rect)*Qrr*Fsw,(R14+Vd_rect)*Qrr*Fsw) -> 0.737616 | AN14: =Vd_rect*t_dead*Fsw*Z14 -> 0.026896 | AO14: =AL14+AM14+AN14 -> 0.77099807 | AP14: =(AA14^2)*R_cs -> 0.024568461 | AQ14: =Rdcr*AA14^2 -> 0.092131728 | AR14: =ABS(7.759*10^-3*Fsw^0.9458*(0.00787*Y14)^2.304) -> 0.0086013784 | AS14: =(Qg_tot+Qg_tot_HS)*Vcc*Fsw -> 0.044 | AT14: =IQ*T14 -> 9.9e-06 | AU14: =AP14+AO14+AI14+AD14+AS14+AT14+AQ14+AR14 -> 2.1924124 | AV14: =R14*S14 -> 10.5 | AW14: =(AV14/(AV14+AU14))*100 -> 82.72659
O15: =0.205*2.5/(Lm*Fsw) -> 0.11647727 | Q15: 8 | R15: =VOUT -> 50 | S15: =Q15*$O$12 -> 0.24 | T15: =VIN_var -> 3 | U15: =(R15*S15)/(T15*EFF_est) -> 4 | V15: =IF(Variable_Management!$B$20=3,2,IF((S15*R15/T15)<((T15*(1-(T15/R15)))/(2*Lm*Fsw)),1,2)) -> 2 | W15: =CHOOSE(V15,SQRT((2*S15*Lm*Fsw*(R15-T15))/((T15)^2)),1-(T15/R15)) -> 0.94 | X15: =CHOOSE(V15,(Lm*Z15*Fsw)/(R15-T15),1-W15) -> 0.06 | Y15: =(T15*W15)/(Lm*Fsw) -> 0.64090909 | Z15: =CHOOSE(V15,Y15,U15+(0.5*Y15)) -> 4.3204545 | AA15: =CHOOSE(V15,Z15*SQRT((W15+X15)/3),SQRT((U15^2)+((Y15^2)/12))) -> 4.0042765 | AB15: 0 | AC15: =(AA15^2)*Rdcr -> 0.12025673 | AD15: =AB15+AC15 -> 0.12025673 | AE15: =U15*W15 -> 3.76 | AF15: =CHOOSE(V15,Z15*SQRT(W15/3),SQRT(W15*((Z15^2)+((Y15^2)/3)-(Z15*Y15)))) -> 3.8822901 | AG15: =(AF15^2)*RDS_on -> 0.56068497 | AH15: =((R15*U15)/2)*Fsw*(tr_sw+tf_sw) -> 0.83476132 | AI15: =AG15+AH15 -> 1.3954463 | AJ15: =X15*U15 -> 0.24 | AK15: =CHOOSE(V15,Z15*SQRT(X15/3),SQRT(X15*((Z15^2)+((Y15^2)/3)-(Y15*Z15)))) -> 0.98084342 | AL15: =(AK15^2)*RDS_on_HS -> 0.0084660736 | AM15: =CHOOSE(V15,(R15+Vd_rect)*Qrr*Fsw,(R15+Vd_rect)*Qrr*Fsw) -> 0.737616 | AN15: =Vd_rect*t_dead*Fsw*Z15 -> 0.030416 | AO15: =AL15+AM15+AN15 -> 0.77649807 | AP15: =(AA15^2)*R_cs -> 0.032068461 | AQ15: =Rdcr*AA15^2 -> 0.12025673 | AR15: =ABS(7.759*10^-3*Fsw^0.9458*(0.00787*Y15)^2.304) -> 0.0086013784 | AS15: =(Qg_tot+Qg_tot_HS)*Vcc*Fsw -> 0.044 | AT15: =IQ*T15 -> 9.9e-06 | AU15: =AP15+AO15+AI15+AD15+AS15+AT15+AQ15+AR15 -> 2.4971376 | AV15: =R15*S15 -> 12 | AW15: =(AV15/(AV15+AU15))*100 -> 82.774961
Q16: 9 | R16: =VOUT -> 50 | S16: =Q16*$O$12 -> 0.27 | T16: =VIN_var -> 3 | U16: =(R16*S16)/(T16*EFF_est) -> 4.5 | V16: =IF(Variable_Management!$B$20=3,2,IF((S16*R16/T16)<((T16*(1-(T16/R16)))/(2*Lm*Fsw)),1,2)) -> 2 | W16: =CHOOSE(V16,SQRT((2*S16*Lm*Fsw*(R16-T16))/((T16)^2)),1-(T16/R16)) -> 0.94 | X16: =CHOOSE(V16,(Lm*Z16*Fsw)/(R16-T16),1-W16) -> 0.06 | Y16: =(T16*W16)/(Lm*Fsw) -> 0.64090909 | Z16: =CHOOSE(V16,Y16,U16+(0.5*Y16)) -> 4.8204545 | AA16: =CHOOSE(V16,Z16*SQRT((W16+X16)/3),SQRT((U16^2)+((Y16^2)/12))) -> 4.5038018 | AB16: 0 | AC16: =(AA16^2)*Rdcr -> 0.15213173 | AD16: =AB16+AC16 -> 0.15213173 | AE16: =U16*W16 -> 4.23 | AF16: =CHOOSE(V16,Z16*SQRT(W16/3),SQRT(W16*((Z16^2)+((Y16^2)/3)-(Z16*Y16)))) -> 4.3665978 | AG16: =(AF16^2)*RDS_on -> 0.70929897 | AH16: =((R16*U16)/2)*Fsw*(tr_sw+tf_sw) -> 0.93910649 | AI16: =AG16+AH16 -> 1.6484055 | AJ16: =X16*U16 -> 0.27 | AK16: =CHOOSE(V16,Z16*SQRT(X16/3),SQRT(X16*((Z16^2)+((Y16^2)/3)-(Y16*Z16)))) -> 1.1032016 | AL16: =(AK16^2)*RDS_on_HS -> 0.010710074 | AM16: =CHOOSE(V16,(R16+Vd_rect)*Qrr*Fsw,(R16+Vd_rect)*Qrr*Fsw) -> 0.737616 | AN16: =Vd_rect*t_dead*Fsw*Z16 -> 0.033936 | AO16: =AL16+AM16+AN16 -> 0.78226207 | AP16: =(AA16^2)*R_cs -> 0.040568461 | AQ16: =Rdcr*AA16^2 -> 0.15213173 | AR16: =ABS(7.759*10^-3*Fsw^0.9458*(0.00787*Y16)^2.304) -> 0.0086013784 | AS16: =(Qg_tot+Qg_tot_HS)*Vcc*Fsw -> 0.044 | AT16: =IQ*T16 -> 9.9e-06 | AU16: =AP16+AO16+AI16+AD16+AS16+AT16+AQ16+AR16 -> 2.8281107 | AV16: =R16*S16 -> 13.5 | AW16: =(AV16/(AV16+AU16))*100 -> 82.679498
Q17: 10 | R17: =VOUT -> 50 | S17: =Q17*$O$12 -> 0.3 | T17: =VIN_var -> 3 | U17: =(R17*S17)/(T17*EFF_est) -> 5 | V17: =IF(Variable_Management!$B$20=3,2,IF((S17*R17/T17)<((T17*(1-(T17/R17)))/(2*Lm*Fsw)),1,2)) -> 2 | W17: =CHOOSE(V17,SQRT((2*S17*Lm*Fsw*(R17-T17))/((T17)^2)),1-(T17/R17)) -> 0.94 | X17: =CHOOSE(V17,(Lm*Z17*Fsw)/(R17-T17),1-W17) -> 0.06 | Y17: =(T17*W17)/(Lm*Fsw) -> 0.64090909 | Z17: =CHOOSE(V17,Y17,U17+(0.5*Y17)) -> 5.3204545 | AA17: =CHOOSE(V17,Z17*SQRT((W17+X17)/3),SQRT((U17^2)+((Y17^2)/12))) -> 5.0034219 | AB17: 0 | AC17: =(AA17^2)*Rdcr -> 0.18775673 | AD17: =AB17+AC17 -> 0.18775673 | AE17: =U17*W17 -> 4.7 | AF17: =CHOOSE(V17,Z17*SQRT(W17/3),SQRT(W17*((Z17^2)+((Y17^2)/3)-(Z17*Y17)))) -> 4.8509975 | AG17: =(AF17^2)*RDS_on -> 0.87539697 | AH17: =((R17*U17)/2)*Fsw*(tr_sw+tf_sw) -> 1.0434517 | AI17: =AG17+AH17 -> 1.9188486 | AJ17: =X17*U17 -> 0.3 | AK17: =CHOOSE(V17,Z17*SQRT(X17/3),SQRT(X17*((Z17^2)+((Y17^2)/3)-(Y17*Z17)))) -> 1.2255831 | AL17: =(AK17^2)*RDS_on_HS -> 0.013218074 | AM17: =CHOOSE(V17,(R17+Vd_rect)*Qrr*Fsw,(R17+Vd_rect)*Qrr*Fsw) -> 0.737616 | AN17: =Vd_rect*t_dead*Fsw*Z17 -> 0.037456 | AO17: =AL17+AM17+AN17 -> 0.78829007 | AP17: =(AA17^2)*R_cs -> 0.050068461 | AQ17: =Rdcr*AA17^2 -> 0.18775673 | AR17: =ABS(7.759*10^-3*Fsw^0.9458*(0.00787*Y17)^2.304) -> 0.0086013784 | AS17: =(Qg_tot+Qg_tot_HS)*Vcc*Fsw -> 0.044 | AT17: =IQ*T17 -> 9.9e-06 | AU17: =AP17+AO17+AI17+AD17+AS17+AT17+AQ17+AR17 -> 3.1853319 | AV17: =R17*S17 -> 15 | AW17: =(AV17/(AV17+AU17))*100 -> 82.48406
Q18: 11 | R18: =VOUT -> 50 | S18: =Q18*$O$12 -> 0.33 | T18: =VIN_var -> 3 | U18: =(R18*S18)/(T18*EFF_est) -> 5.5 | V18: =IF(Variable_Management!$B$20=3,2,IF((S18*R18/T18)<((T18*(1-(T18/R18)))/(2*Lm*Fsw)),1,2)) -> 2 | W18: =CHOOSE(V18,SQRT((2*S18*Lm*Fsw*(R18-T18))/((T18)^2)),1-(T18/R18)) -> 0.94 | X18: =CHOOSE(V18,(Lm*Z18*Fsw)/(R18-T18),1-W18) -> 0.06 | Y18: =(T18*W18)/(Lm*Fsw) -> 0.64090909 | Z18: =CHOOSE(V18,Y18,U18+(0.5*Y18)) -> 5.8204545 | AA18: =CHOOSE(V18,Z18*SQRT((W18+X18)/3),SQRT((U18^2)+((Y18^2)/12))) -> 5.503111 | AB18: 0 | AC18: =(AA18^2)*Rdcr -> 0.22713173 | AD18: =AB18+AC18 -> 0.22713173 | AE18: =U18*W18 -> 5.17 | AF18: =CHOOSE(V18,Z18*SQRT(W18/3),SQRT(W18*((Z18^2)+((Y18^2)/3)-(Z18*Y18)))) -> 5.335464 | AG18: =(AF18^2)*RDS_on -> 1.058979 | AH18: =((R18*U18)/2)*Fsw*(tr_sw+tf_sw) -> 1.1477968 | AI18: =AG18+AH18 -> 2.2067758 | AJ18: =X18*U18 -> 0.33 | AK18: =CHOOSE(V18,Z18*SQRT(X18/3),SQRT(X18*((Z18^2)+((Y18^2)/3)-(Y18*Z18)))) -> 1.3479814 | AL18: =(AK18^2)*RDS_on_HS -> 0.015990074 | AM18: =CHOOSE(V18,(R18+Vd_rect)*Qrr*Fsw,(R18+Vd_rect)*Qrr*Fsw) -> 0.737616 | AN18: =Vd_rect*t_dead*Fsw*Z18 -> 0.040976 | AO18: =AL18+AM18+AN18 -> 0.79458207 | AP18: =(AA18^2)*R_cs -> 0.060568461 | AQ18: =Rdcr*AA18^2 -> 0.22713173 | AR18: =ABS(7.759*10^-3*Fsw^0.9458*(0.00787*Y18)^2.304) -> 0.0086013784 | AS18: =(Qg_tot+Qg_tot_HS)*Vcc*Fsw -> 0.044 | AT18: =IQ*T18 -> 9.9e-06 | AU18: =AP18+AO18+AI18+AD18+AS18+AT18+AQ18+AR18 -> 3.5688011 | AV18: =R18*S18 -> 16.5 | AW18: =(AV18/(AV18+AU18))*100 -> 82.217169
Q19: 12 | R19: =VOUT -> 50 | S19: =Q19*$O$12 -> 0.36 | T19: =VIN_var -> 3 | U19: =(R19*S19)/(T19*EFF_est) -> 6 | V19: =IF(Variable_Management!$B$20=3,2,IF((S19*R19/T19)<((T19*(1-(T19/R19)))/(2*Lm*Fsw)),1,2)) -> 2 | W19: =CHOOSE(V19,SQRT((2*S19*Lm*Fsw*(R19-T19))/((T19)^2)),1-(T19/R19)) -> 0.94 | X19: =CHOOSE(V19,(Lm*Z19*Fsw)/(R19-T19),1-W19) -> 0.06 | Y19: =(T19*W19)/(Lm*Fsw) -> 0.64090909 | Z19: =CHOOSE(V19,Y19,U19+(0.5*Y19)) -> 6.3204545 | AA19: =CHOOSE(V19,Z19*SQRT((W19+X19)/3),SQRT((U19^2)+((Y19^2)/12))) -> 6.0028519 | AB19: 0 | AC19: =(AA19^2)*Rdcr -> 0.27025673 | AD19: =AB19+AC19 -> 0.27025673 | AE19: =U19*W19 -> 5.64 | AF19: =CHOOSE(V19,Z19*SQRT(W19/3),SQRT(W19*((Z19^2)+((Y19^2)/3)-(Z19*Y19)))) -> 5.8199808 | AG19: =(AF19^2)*RDS_on -> 1.260045 | AH19: =((R19*U19)/2)*Fsw*(tr_sw+tf_sw) -> 1.252142 | AI19: =AG19+AH19 -> 2.512187 | AJ19: =X19*U19 -> 0.36 | AK19: =CHOOSE(V19,Z19*SQRT(X19/3),SQRT(X19*((Z19^2)+((Y19^2)/3)-(Y19*Z19)))) -> 1.4703924 | AL19: =(AK19^2)*RDS_on_HS -> 0.019026074 | AM19: =CHOOSE(V19,(R19+Vd_rect)*Qrr*Fsw,(R19+Vd_rect)*Qrr*Fsw) -> 0.737616 | AN19: =Vd_rect*t_dead*Fsw*Z19 -> 0.044496 | AO19: =AL19+AM19+AN19 -> 0.80113807 | AP19: =(AA19^2)*R_cs -> 0.072068461 | AQ19: =Rdcr*AA19^2 -> 0.27025673 | AR19: =ABS(7.759*10^-3*Fsw^0.9458*(0.00787*Y19)^2.304) -> 0.0086013784 | AS19: =(Qg_tot+Qg_tot_HS)*Vcc*Fsw -> 0.044 | AT19: =IQ*T19 -> 9.9e-06 | AU19: =AP19+AO19+AI19+AD19+AS19+AT19+AQ19+AR19 -> 3.9785182 | AV19: =R19*S19 -> 18 | AW19: =(AV19/(AV19+AU19))*100 -> 81.898151
Q20: 13 | R20: =VOUT -> 50 | S20: =Q20*$O$12 -> 0.39 | T20: =VIN_var -> 3 | U20: =(R20*S20)/(T20*EFF_est) -> 6.5 | V20: =IF(Variable_Management!$B$20=3,2,IF((S20*R20/T20)<((T20*(1-(T20/R20)))/(2*Lm*Fsw)),1,2)) -> 2 | W20: =CHOOSE(V20,SQRT((2*S20*Lm*Fsw*(R20-T20))/((T20)^2)),1-(T20/R20)) -> 0.94 | X20: =CHOOSE(V20,(Lm*Z20*Fsw)/(R20-T20),1-W20) -> 0.06 | Y20: =(T20*W20)/(Lm*Fsw) -> 0.64090909 | Z20: =CHOOSE(V20,Y20,U20+(0.5*Y20)) -> 6.8204545 | AA20: =CHOOSE(V20,Z20*SQRT((W20+X20)/3),SQRT((U20^2)+((Y20^2)/12))) -> 6.5026326 | AB20: 0 | AC20: =(AA20^2)*Rdcr -> 0.31713173 | AD20: =AB20+AC20 -> 0.31713173 | AE20: =U20*W20 -> 6.11 | AF20: =CHOOSE(V20,Z20*SQRT(W20/3),SQRT(W20*((Z20^2)+((Y20^2)/3)-(Z20*Y20)))) -> 6.3045362 | AG20: =(AF20^2)*RDS_on -> 1.478595 | AH20: =((R20*U20)/2)*Fsw*(tr_sw+tf_sw) -> 1.3564871 | AI20: =AG20+AH20 -> 2.8350821 | AJ20: =X20*U20 -> 0.39 | AK20: =CHOOSE(V20,Z20*SQRT(X20/3),SQRT(X20*((Z20^2)+((Y20^2)/3)-(Y20*Z20)))) -> 1.5928132 | AL20: =(AK20^2)*RDS_on_HS -> 0.022326074 | AM20: =CHOOSE(V20,(R20+Vd_rect)*Qrr*Fsw,(R20+Vd_rect)*Qrr*Fsw) -> 0.737616 | AN20: =Vd_rect*t_dead*Fsw*Z20 -> 0.048016 | AO20: =AL20+AM20+AN20 -> 0.80795807 | AP20: =(AA20^2)*R_cs -> 0.084568461 | AQ20: =Rdcr*AA20^2 -> 0.31713173 | AR20: =ABS(7.759*10^-3*Fsw^0.9458*(0.00787*Y20)^2.304) -> 0.0086013784 | AS20: =(Qg_tot+Qg_tot_HS)*Vcc*Fsw -> 0.044 | AT20: =IQ*T20 -> 9.9e-06 | AU20: =AP20+AO20+AI20+AD20+AS20+AT20+AQ20+AR20 -> 4.4144834 | AV20: =R20*S20 -> 19.5 | AW20: =(AV20/(AV20+AU20))*100 -> 81.540545
Q21: 14 | R21: =VOUT -> 50 | S21: =Q21*$O$12 -> 0.42 | T21: =VIN_var -> 3 | U21: =(R21*S21)/(T21*EFF_est) -> 7 | V21: =IF(Variable_Management!$B$20=3,2,IF((S21*R21/T21)<((T21*(1-(T21/R21)))/(2*Lm*Fsw)),1,2)) -> 2 | W21: =CHOOSE(V21,SQRT((2*S21*Lm*Fsw*(R21-T21))/((T21)^2)),1-(T21/R21)) -> 0.94 | X21: =CHOOSE(V21,(Lm*Z21*Fsw)/(R21-T21),1-W21) -> 0.06 | Y21: =(T21*W21)/(Lm*Fsw) -> 0.64090909 | Z21: =CHOOSE(V21,Y21,U21+(0.5*Y21)) -> 7.3204545 | AA21: =CHOOSE(V21,Z21*SQRT((W21+X21)/3),SQRT((U21^2)+((Y21^2)/12))) -> 7.0024446 | AB21: 0 | AC21: =(AA21^2)*Rdcr -> 0.36775673 | AD21: =AB21+AC21 -> 0.36775673 | AE21: =U21*W21 -> 6.58 | AF21: =CHOOSE(V21,Z21*SQRT(W21/3),SQRT(W21*((Z21^2)+((Y21^2)/3)-(Z21*Y21)))) -> 6.7891219 | AG21: =(AF21^2)*RDS_on -> 1.714629 | AH21: =((R21*U21)/2)*Fsw*(tr_sw+tf_sw) -> 1.4608323 | AI21: =AG21+AH21 -> 3.1754613 | AJ21: =X21*U21 -> 0.42 | AK21: =CHOOSE(V21,Z21*SQRT(X21/3),SQRT(X21*((Z21^2)+((Y21^2)/3)-(Y21*Z21)))) -> 1.7152416 | AL21: =(AK21^2)*RDS_on_HS -> 0.025890074 | AM21: =CHOOSE(V21,(R21+Vd_rect)*Qrr*Fsw,(R21+Vd_rect)*Qrr*Fsw) -> 0.737616 | AN21: =Vd_rect*t_dead*Fsw*Z21 -> 0.051536 | AO21: =AL21+AM21+AN21 -> 0.81504207 | AP21: =(AA21^2)*R_cs -> 0.098068461 | AQ21: =Rdcr*AA21^2 -> 0.36775673 | AR21: =ABS(7.759*10^-3*Fsw^0.9458*(0.00787*Y21)^2.304) -> 0.0086013784 | AS21: =(Qg_tot+Qg_tot_HS)*Vcc*Fsw -> 0.044 | AT21: =IQ*T21 -> 9.9e-06 | AU21: =AP21+AO21+AI21+AD21+AS21+AT21+AQ21+AR21 -> 4.8766965 | AV21: =R21*S21 -> 21 | AW21: =(AV21/(AV21+AU21))*100 -> 81.154099
Q22: 15 | R22: =VOUT -> 50 | S22: =Q22*$O$12 -> 0.45 | T22: =VIN_var -> 3 | U22: =(R22*S22)/(T22*EFF_est) -> 7.5 | V22: =IF(Variable_Management!$B$20=3,2,IF((S22*R22/T22)<((T22*(1-(T22/R22)))/(2*Lm*Fsw)),1,2)) -> 2 | W22: =CHOOSE(V22,SQRT((2*S22*Lm*Fsw*(R22-T22))/((T22)^2)),1-(T22/R22)) -> 0.94 | X22: =CHOOSE(V22,(Lm*Z22*Fsw)/(R22-T22),1-W22) -> 0.06 | Y22: =(T22*W22)/(Lm*Fsw) -> 0.64090909 | Z22: =CHOOSE(V22,Y22,U22+(0.5*Y22)) -> 7.8204545 | AA22: =CHOOSE(V22,Z22*SQRT((W22+X22)/3),SQRT((U22^2)+((Y22^2)/12))) -> 7.5022817 | AB22: 0 | AC22: =(AA22^2)*Rdcr -> 0.42213173 | AD22: =AB22+AC22 -> 0.42213173 | AE22: =U22*W22 -> 7.05 | AF22: =CHOOSE(V22,Z22*SQRT(W22/3),SQRT(W22*((Z22^2)+((Y22^2)/3)-(Z22*Y22)))) -> 7.273732 | AG22: =(AF22^2)*RDS_on -> 1.968147 | AH22: =((R22*U22)/2)*Fsw*(tr_sw+tf_sw) -> 1.5651775 | AI22: =AG22+AH22 -> 3.5333244 | AJ22: =X22*U22 -> 0.45 | AK22: =CHOOSE(V22,Z22*SQRT(X22/3),SQRT(X22*((Z22^2)+((Y22^2)/3)-(Y22*Z22)))) -> 1.8376762 | AL22: =(AK22^2)*RDS_on_HS -> 0.029718074 | AM22: =CHOOSE(V22,(R22+Vd_rect)*Qrr*Fsw,(R22+Vd_rect)*Qrr*Fsw) -> 0.737616 | AN22: =Vd_rect*t_dead*Fsw*Z22 -> 0.055056 | AO22: =AL22+AM22+AN22 -> 0.82239007 | AP22: =(AA22^2)*R_cs -> 0.11256846 | AQ22: =Rdcr*AA22^2 -> 0.42213173 | AR22: =ABS(7.759*10^-3*Fsw^0.9458*(0.00787*Y22)^2.304) -> 0.0086013784 | AS22: =(Qg_tot+Qg_tot_HS)*Vcc*Fsw -> 0.044 | AT22: =IQ*T22 -> 9.9e-06 | AU22: =AP22+AO22+AI22+AD22+AS22+AT22+AQ22+AR22 -> 5.3651577 | AV22: =R22*S22 -> 22.5 | AW22: =(AV22/(AV22+AU22))*100 -> 80.745999
Q23: 16 | R23: =VOUT -> 50 | S23: =Q23*$O$12 -> 0.48 | T23: =VIN_var -> 3 | U23: =(R23*S23)/(T23*EFF_est) -> 8 | V23: =IF(Variable_Management!$B$20=3,2,IF((S23*R23/T23)<((T23*(1-(T23/R23)))/(2*Lm*Fsw)),1,2)) -> 2 | W23: =CHOOSE(V23,SQRT((2*S23*Lm*Fsw*(R23-T23))/((T23)^2)),1-(T23/R23)) -> 0.94 | X23: =CHOOSE(V23,(Lm*Z23*Fsw)/(R23-T23),1-W23) -> 0.06 | Y23: =(T23*W23)/(Lm*Fsw) -> 0.64090909 | Z23: =CHOOSE(V23,Y23,U23+(0.5*Y23)) -> 8.3204545 | AA23: =CHOOSE(V23,Z23*SQRT((W23+X23)/3),SQRT((U23^2)+((Y23^2)/12))) -> 8.0021391 | AB23: 0 | AC23: =(AA23^2)*Rdcr -> 0.48025673 | AD23: =AB23+AC23 -> 0.48025673 | AE23: =U23*W23 -> 7.52 | AF23: =CHOOSE(V23,Z23*SQRT(W23/3),SQRT(W23*((Z23^2)+((Y23^2)/3)-(Z23*Y23)))) -> 7.7583617 | AG23: =(AF23^2)*RDS_on -> 2.239149 | AH23: =((R23*U23)/2)*Fsw*(tr_sw+tf_sw) -> 1.6695226 | AI23: =AG23+AH23 -> 3.9086716 | AJ23: =X23*U23 -> 0.48 | AK23: =CHOOSE(V23,Z23*SQRT(X23/3),SQRT(X23*((Z23^2)+((Y23^2)/3)-(Y23*Z23)))) -> 1.9601158 | AL23: =(AK23^2)*RDS_on_HS -> 0.033810074 | AM23: =CHOOSE(V23,(R23+Vd_rect)*Qrr*Fsw,(R23+Vd_rect)*Qrr*Fsw) -> 0.737616 | AN23: =Vd_rect*t_dead*Fsw*Z23 -> 0.058576 | AO23: =AL23+AM23+AN23 -> 0.83000207 | AP23: =(AA23^2)*R_cs -> 0.12806846 | AQ23: =Rdcr*AA23^2 -> 0.48025673 | AR23: =ABS(7.759*10^-3*Fsw^0.9458*(0.00787*Y23)^2.304) -> 0.0086013784 | AS23: =(Qg_tot+Qg_tot_HS)*Vcc*Fsw -> 0.044 | AT23: =IQ*T23 -> 9.9e-06 | AU23: =AP23+AO23+AI23+AD23+AS23+AT23+AQ23+AR23 -> 5.8798669 | AV23: =R23*S23 -> 24 | AW23: =(AV23/(AV23+AU23))*100 -> 80.321643
Q24: 17 | R24: =VOUT -> 50 | S24: =Q24*$O$12 -> 0.51 | T24: =VIN_var -> 3 | U24: =(R24*S24)/(T24*EFF_est) -> 8.5 | V24: =IF(Variable_Management!$B$20=3,2,IF((S24*R24/T24)<((T24*(1-(T24/R24)))/(2*Lm*Fsw)),1,2)) -> 2 | W24: =CHOOSE(V24,SQRT((2*S24*Lm*Fsw*(R24-T24))/((T24)^2)),1-(T24/R24)) -> 0.94 | X24: =CHOOSE(V24,(Lm*Z24*Fsw)/(R24-T24),1-W24) -> 0.06 | Y24: =(T24*W24)/(Lm*Fsw) -> 0.64090909 | Z24: =CHOOSE(V24,Y24,U24+(0.5*Y24)) -> 8.8204545 | AA24: =CHOOSE(V24,Z24*SQRT((W24+X24)/3),SQRT((U24^2)+((Y24^2)/12))) -> 8.5020133 | AB24: 0 | AC24: =(AA24^2)*Rdcr -> 0.54213173 | AD24: =AB24+AC24 -> 0.54213173 | AE24: =U24*W24 -> 7.99 | AF24: =CHOOSE(V24,Z24*SQRT(W24/3),SQRT(W24*((Z24^2)+((Y24^2)/3)-(Z24*Y24)))) -> 8.2430077 | AG24: =(AF24^2)*RDS_on -> 2.527635 | AH24: =((R24*U24)/2)*Fsw*(tr_sw+tf_sw) -> 1.7738678 | AI24: =AG24+AH24 -> 4.3015028 | AJ24: =X24*U24 -> 0.51 | AK24: =CHOOSE(V24,Z24*SQRT(X24/3),SQRT(X24*((Z24^2)+((Y24^2)/3)-(Y24*Z24)))) -> 2.0825594 | AL24: =(AK24^2)*RDS_on_HS -> 0.038166074 | AM24: =CHOOSE(V24,(R24+Vd_rect)*Qrr*Fsw,(R24+Vd_rect)*Qrr*Fsw) -> 0.737616 | AN24: =Vd_rect*t_dead*Fsw*Z24 -> 0.062096 | AO24: =AL24+AM24+AN24 -> 0.83787807 | AP24: =(AA24^2)*R_cs -> 0.14456846 | AQ24: =Rdcr*AA24^2 -> 0.54213173 | AR24: =ABS(7.759*10^-3*Fsw^0.9458*(0.00787*Y24)^2.304) -> 0.0086013784 | AS24: =(Qg_tot+Qg_tot_HS)*Vcc*Fsw -> 0.044 | AT24: =IQ*T24 -> 9.9e-06 | AU24: =AP24+AO24+AI24+AD24+AS24+AT24+AQ24+AR24 -> 6.420824 | AV24: =R24*S24 -> 25.5 | AW24: =(AV24/(AV24+AU24))*100 -> 79.885156
Q25: 18 | R25: =VOUT -> 50 | S25: =Q25*$O$12 -> 0.54 | T25: =VIN_var -> 3 | U25: =(R25*S25)/(T25*EFF_est) -> 9 | V25: =IF(Variable_Management!$B$20=3,2,IF((S25*R25/T25)<((T25*(1-(T25/R25)))/(2*Lm*Fsw)),1,2)) -> 2 | W25: =CHOOSE(V25,SQRT((2*S25*Lm*Fsw*(R25-T25))/((T25)^2)),1-(T25/R25)) -> 0.94 | X25: =CHOOSE(V25,(Lm*Z25*Fsw)/(R25-T25),1-W25) -> 0.06 | Y25: =(T25*W25)/(Lm*Fsw) -> 0.64090909 | Z25: =CHOOSE(V25,Y25,U25+(0.5*Y25)) -> 9.3204545 | AA25: =CHOOSE(V25,Z25*SQRT((W25+X25)/3),SQRT((U25^2)+((Y25^2)/12))) -> 9.0019015 | AB25: 0 | AC25: =(AA25^2)*Rdcr -> 0.60775673 | AD25: =AB25+AC25 -> 0.60775673 | AE25: =U25*W25 -> 8.46 | AF25: =CHOOSE(V25,Z25*SQRT(W25/3),SQRT(W25*((Z25^2)+((Y25^2)/3)-(Z25*Y25)))) -> 8.7276673 | AG25: =(AF25^2)*RDS_on -> 2.833605 | AH25: =((R25*U25)/2)*Fsw*(tr_sw+tf_sw) -> 1.878213 | AI25: =AG25+AH25 -> 4.7118179 | AJ25: =X25*U25 -> 0.54 | AK25: =CHOOSE(V25,Z25*SQRT(X25/3),SQRT(X25*((Z25^2)+((Y25^2)/3)-(Y25*Z25)))) -> 2.2050065 | AL25: =(AK25^2)*RDS_on_HS -> 0.042786074 | AM25: =CHOOSE(V25,(R25+Vd_rect)*Qrr*Fsw,(R25+Vd_rect)*Qrr*Fsw) -> 0.737616 | AN25: =Vd_rect*t_dead*Fsw*Z25 -> 0.065616 | AO25: =AL25+AM25+AN25 -> 0.84601807 | AP25: =(AA25^2)*R_cs -> 0.16206846 | AQ25: =Rdcr*AA25^2 -> 0.60775673 | AR25: =ABS(7.759*10^-3*Fsw^0.9458*(0.00787*Y25)^2.304) -> 0.0086013784 | AS25: =(Qg_tot+Qg_tot_HS)*Vcc*Fsw -> 0.044 | AT25: =IQ*T25 -> 9.9e-06 | AU25: =AP25+AO25+AI25+AD25+AS25+AT25+AQ25+AR25 -> 6.9880292 | AV25: =R25*S25 -> 27 | AW25: =(AV25/(AV25+AU25))*100 -> 79.439734
Q26: 19 | R26: =VOUT -> 50 | S26: =Q26*$O$12 -> 0.57 | T26: =VIN_var -> 3 | U26: =(R26*S26)/(T26*EFF_est) -> 9.5 | V26: =IF(Variable_Management!$B$20=3,2,IF((S26*R26/T26)<((T26*(1-(T26/R26)))/(2*Lm*Fsw)),1,2)) -> 2 | W26: =CHOOSE(V26,SQRT((2*S26*Lm*Fsw*(R26-T26))/((T26)^2)),1-(T26/R26)) -> 0.94 | X26: =CHOOSE(V26,(Lm*Z26*Fsw)/(R26-T26),1-W26) -> 0.06 | Y26: =(T26*W26)/(Lm*Fsw) -> 0.64090909 | Z26: =CHOOSE(V26,Y26,U26+(0.5*Y26)) -> 9.8204545 | AA26: =CHOOSE(V26,Z26*SQRT((W26+X26)/3),SQRT((U26^2)+((Y26^2)/12))) -> 9.5018014 | AB26: 0 | AC26: =(AA26^2)*Rdcr -> 0.67713173 | AD26: =AB26+AC26 -> 0.67713173 | AE26: =U26*W26 -> 8.93 | AF26: =CHOOSE(V26,Z26*SQRT(W26/3),SQRT(W26*((Z26^2)+((Y26^2)/3)-(Z26*Y26)))) -> 9.2123383 | AG26: =(AF26^2)*RDS_on -> 3.157059 | AH26: =((R26*U26)/2)*Fsw*(tr_sw+tf_sw) -> 1.9825581 | AI26: =AG26+AH26 -> 5.1396171 | AJ26: =X26*U26 -> 0.57 | AK26: =CHOOSE(V26,Z26*SQRT(X26/3),SQRT(X26*((Z26^2)+((Y26^2)/3)-(Y26*Z26)))) -> 2.3274565 | AL26: =(AK26^2)*RDS_on_HS -> 0.047670074 | AM26: =CHOOSE(V26,(R26+Vd_rect)*Qrr*Fsw,(R26+Vd_rect)*Qrr*Fsw) -> 0.737616 | AN26: =Vd_rect*t_dead*Fsw*Z26 -> 0.069136 | AO26: =AL26+AM26+AN26 -> 0.85442207 | AP26: =(AA26^2)*R_cs -> 0.18056846 | AQ26: =Rdcr*AA26^2 -> 0.67713173 | AR26: =ABS(7.759*10^-3*Fsw^0.9458*(0.00787*Y26)^2.304) -> 0.0086013784 | AS26: =(Qg_tot+Qg_tot_HS)*Vcc*Fsw -> 0.044 | AT26: =IQ*T26 -> 9.9e-06 | AU26: =AP26+AO26+AI26+AD26+AS26+AT26+AQ26+AR26 -> 7.5814824 | AV26: =R26*S26 -> 28.5 | AW26: =(AV26/(AV26+AU26))*100 -> 78.987886
Q27: 20 | R27: =VOUT -> 50 | S27: =Q27*$O$12 -> 0.6 | T27: =VIN_var -> 3 | U27: =(R27*S27)/(T27*EFF_est) -> 10 | V27: =IF(Variable_Management!$B$20=3,2,IF((S27*R27/T27)<((T27*(1-(T27/R27)))/(2*Lm*Fsw)),1,2)) -> 2 | W27: =CHOOSE(V27,SQRT((2*S27*Lm*Fsw*(R27-T27))/((T27)^2)),1-(T27/R27)) -> 0.94 | X27: =CHOOSE(V27,(Lm*Z27*Fsw)/(R27-T27),1-W27) -> 0.06 | Y27: =(T27*W27)/(Lm*Fsw) -> 0.64090909 | Z27: =CHOOSE(V27,Y27,U27+(0.5*Y27)) -> 10.320455 | AA27: =CHOOSE(V27,Z27*SQRT((W27+X27)/3),SQRT((U27^2)+((Y27^2)/12))) -> 10.001711 | AB27: 0 | AC27: =(AA27^2)*Rdcr -> 0.75025673 | AD27: =AB27+AC27 -> 0.75025673 | AE27: =U27*W27 -> 9.4 | AF27: =CHOOSE(V27,Z27*SQRT(W27/3),SQRT(W27*((Z27^2)+((Y27^2)/3)-(Z27*Y27)))) -> 9.697019 | AG27: =(AF27^2)*RDS_on -> 3.497997 | AH27: =((R27*U27)/2)*Fsw*(tr_sw+tf_sw) -> 2.0869033 | AI27: =AG27+AH27 -> 5.5849003 | AJ27: =X27*U27 -> 0.6 | AK27: =CHOOSE(V27,Z27*SQRT(X27/3),SQRT(X27*((Z27^2)+((Y27^2)/3)-(Y27*Z27)))) -> 2.4499089 | AL27: =(AK27^2)*RDS_on_HS -> 0.052818074 | AM27: =CHOOSE(V27,(R27+Vd_rect)*Qrr*Fsw,(R27+Vd_rect)*Qrr*Fsw) -> 0.737616 | AN27: =Vd_rect*t_dead*Fsw*Z27 -> 0.072656 | AO27: =AL27+AM27+AN27 -> 0.86309007 | AP27: =(AA27^2)*R_cs -> 0.20006846 | AQ27: =Rdcr*AA27^2 -> 0.75025673 | AR27: =ABS(7.759*10^-3*Fsw^0.9458*(0.00787*Y27)^2.304) -> 0.0086013784 | AS27: =(Qg_tot+Qg_tot_HS)*Vcc*Fsw -> 0.044 | AT27: =IQ*T27 -> 9.9e-06 | AU27: =AP27+AO27+AI27+AD27+AS27+AT27+AQ27+AR27 -> 8.2011835 | AV27: =R27*S27 -> 30 | AW27: =(AV27/(AV27+AU27))*100 -> 78.531598
... Q157: 150 | R157: =VOUT -> 50 | S157: =Q157*$O$12 -> 4.5 | T157: =VIN_var -> 3 | U157: =(R157*S157)/(T157*EFF_est) -> 75 | V157: =IF(Variable_Management!$B$20=3,2,IF((S157*R157/T157)<((T157*(1-(T157/R157)))/(2*Lm*Fsw)),1,2)) -> 2 | W157: =CHOOSE(V157,SQRT((2*S157*Lm*Fsw*(R157-T157))/((T157)^2)),1-(T157/R157)) -> 0.94 | X157: =CHOOSE(V157,(Lm*Z157*Fsw)/(R157-T157),1-W157) -> 0.06 | Y157: =(T157*W157)/(Lm*Fsw) -> 0.64090909 | Z157: =CHOOSE(V157,Y157,U157+(0.5*Y157)) -> 75.320455 | AA157: =CHOOSE(V157,Z157*SQRT((W157+X157)/3),SQRT((U157^2)+((Y157^2)/12))) -> 75.000228 | AB157: 0 | AC157: =(AA157^2)*Rdcr -> 42.187757 | AD157: =AB157+AC157 -> 42.187757 | AE157: =U157*W157 -> 70.5 | AF157: =CHOOSE(V157,Z157*SQRT(W157/3),SQRT(W157*((Z157^2)+((Y157^2)/3)-(Z157*Y157)))) -> 72.715419 | AG157: =(AF157^2)*RDS_on -> 196.6962 | AH157: =((R157*U157)/2)*Fsw*(tr_sw+tf_sw) -> 15.651775 | AI157: =AG157+AH157 -> 212.34797 | AJ157: =X157*U157 -> 4.5 | AK157: =CHOOSE(V157,Z157*SQRT(X157/3),SQRT(X157*((Z157^2)+((Y157^2)/3)-(Y157*Z157)))) -> 18.371229 | AL157: =(AK157^2)*RDS_on_HS -> 2.9700181 | AM157: =CHOOSE(V157,(R157+Vd_rect)*Qrr*Fsw,(R157+Vd_rect)*Qrr*Fsw) -> 0.737616 | AN157: =Vd_rect*t_dead*Fsw*Z157 -> 0.530256 | AO157: =AL157+AM157+AN157 -> 4.2378901 | AP157: =(AA157^2)*R_cs -> 11.250068 | AQ157: =Rdcr*AA157^2 -> 42.187757 | AR157: =ABS(7.759*10^-3*Fsw^0.9458*(0.00787*Y157)^2.304) -> 0.0086013784 | AS157: =(Qg_tot+Qg_tot_HS)*Vcc*Fsw -> 0.044 | AT157: =IQ*T157 -> 9.9e-06 | AU157: =AP157+AO157+AI157+AD157+AS157+AT157+AQ157+AR157 -> 312.26406 | AV157: =R157*S157 -> 225 | AW157: =(AV157/(AV157+AU157))*100 -> 41.878849

Sheet Loop_Modeling
A1: EXCEL Variables Names/Calculations | N1: Calculations
B2: Input from user =
B3: Output = | O3: Operating mode
B4: Constant | P4: CCM Plant Transfer Function | AF4: DCM Operation Loop Model | AS4: Error Amplifier | BF4: CCM Open Loop Response | BI4: DCM Open Loop Response | BL4: Displayed Loop Calclation
Q5: wp_lf | T5: wz_esr | W5: wz_esr | Z5: Sampling | AC5: Total | AG5: wp_lf | AJ5: wz_esr | AM5: wz_RHP | AP5: Total | AT5: wp0_ea | AW5: wp1_ea | AZ5: wz_ea | BC5: Total | BF5: Total | BI5: Total | BL5: Total
A6: Variable Name | B6: Value | C6: STD Units | E6: Notes | P6: ADC | Q6: Complex | R6: Gain | S6: Phase | T6: Complex | U6: Gain | V6: Phase | W6: Complex | X6: Gain | Y6: Phase | Z6: Complex | AA6: Gain | AB6: Phase | AC6: COMPLEX | AD6: Gain | AE6: Phase | AF6: ADC | AG6: Complex | AH6: Gain | AI6: Phase | AJ6: Complex | AK6: Gain | AL6: Phase | AM6: Complex | AN6: Gain | AO6: Phase | AP6: COMPLEX | AQ6: Gain | AR6: Phase | AS6: ADC_ea | AT6: Complex | AU6: Gain | AV6: Phase | AW6: Complex | AX6: Gain | AY6: Phase | AZ6: Complex | BA6: Gain | BB6: Phase | BC6: COMPLEX | BD6: Gain | BE6: Phase | BF6: COMPLEX | BG6: Gain | BH6: Phase | BI6: COMPLEX | BJ6: Gain | BK6: Phase | BL6: Gain | BM6: Phase
N7: Frcoss (VIN)min | O7: =fcross -> 1400 | P7: =COMPLEX(ADC_VINmin,0) -> 50.2742230347349 | Q7: =IMSUM(COMPLEX(1,0),IMDIV(COMPLEX(0,2*PI()*O7),COMPLEX(wp_lf_VINmin,0))) -> 1+20.7850526752129i | R7: =IMABS(Q7) -> 20.809095 | S7: =IMARGUMENT(Q7) -> 1.5227219 | T7: =IMSUM(COMPLEX(1,0),IMDIV(COMPLEX(0,2*PI()*O7),COMPLEX(wz_esr_VINmin,0))) -> 1+0.144701757624346i | U7: =IMABS(T7) -> 1.0104151 | V7: =IMARGUMENT(T7) -> 0.14370431 | W7: =IMSUB(COMPLEX(1,0),IMDIV(COMPLEX(0,2*PI()*O7),COMPLEX(wz_RHP_VINmin,0))) -> 1-0.197920337176157i | X7: =IMABS(W7) -> 1.0193981 | Y7: =IMARGUMENT(W7) -> -0.19539509 | Z7: =IMSUM(COMPLEX(1,0),IMDIV(COMPLEX(0,2*PI()*O7),COMPLEX(Q_VINmin*(wsl_VINmin/2),0)),IMDIV(IMPOWER(COMPLEX(0,2*PI()*O7),2),IMPOWER(COMPLEX(wsl_VINmin/2,0),2))) -> 0.999959504132231+0.0335864814601963i | AA7: =IMABS(Z7) -> 1.0005234 | AB7: =IMARGUMENT(Z7) -> 0.03357522 | AC7: =(IMDIV(IMPRODUCT(P7,T7,W7),IMPRODUCT(Q7,Z7))) -> -0.092481094206573-2.48546775327198i | AD7: =20*LOG(IMABS(AC7)) -> 7.9141713 | AE7: =(180/PI())*IMARGUMENT(AC7) -> -92.13092 | AF7: =COMPLEX($B$72,0) -> 247.084651286898 | AG7: =IMSUM(COMPLEX(1,0),IMDIV(COMPLEX(0,2*PI()*O7),COMPLEX(wp_lf_DCM,0))) -> 1+22.2581659575986i | AH7: =IMABS(AG7) -> 22.280618 | AI7: =IMARGUMENT(AG7) -> 1.5258992 | AJ7: =IMSUM(COMPLEX(1,0),IMDIV(COMPLEX(0,2*PI()*O7),COMPLEX(wz1_dcm,0))) -> 1+0.144701757624346i | AK7: =IMABS(AJ7) -> 1.0104151 | AL7: =IMARGUMENT(AJ7) -> 0.14370431 | AM7: =IMSUB(COMPLEX(1,0),IMDIV(COMPLEX(0,2*PI()*O7),COMPLEX(wz2_dcm,0))) -> 1-0.143747565784003i | AN7: =IMABS(AM7) -> 1.0102789 | AO7: =IMARGUMENT(AM7) -> -0.14276956 | AP7: =(IMDIV(IMPRODUCT(AF7,AJ7,AM7),IMPRODUCT(AG7))) -> 0.518651096303595-11.3084560174839i | AQ7: =20*LOG(IMABS(AP7)) -> 21.077192 | AR7: =(180/PI())*IMARGUMENT(AP7) -> -87.374026 | AS7: =COMPLEX(Adc_ea,0) -> -0.0000166666666666667 | AT7: =COMPLEX(0,2*PI()*O7*wp0_ea) -> 0.0000299079620621748i | AU7: =IMABS(AT7) -> 2.9907962e-05 | AV7: =IMARGUMENT(AT7) -> 1.5707963 | AW7: =IMSUM(COMPLEX(1,0),IMDIV(COMPLEX(0,2*PI()*O7),COMPLEX(wp1_ea,0))) -> 1+0.0303943545247777i | AX7: =IMABS(AW7) -> 1.0004618 | AY7: =IMARGUMENT(AW7) -> 0.030385 | AZ7: =IMSUM(COMPLEX(1,0),IMDIV(COMPLEX(0,2*PI()*O7),COMPLEX(wz_ea,0))) -> 1+1.03340805384244i | BA7: =IMABS(AZ7) -> 1.4380307 | BB7: =IMARGUMENT(AZ7) -> 0.80182627 | BC7: =IMPRODUCT(AS7,IMDIV(AZ7,IMPRODUCT(AT7,AW7))) -> -0.55842875082386+0.574238288333766i | BD7: =20*LOG(IMABS(BC7)) -> -1.9274087 | BE7: =(180/PI())*IMARGUMENT(BC7) -> 134.20033 | BF7: =IMPRODUCT(AC7,BC7) -> 1.47889485026027+1.33485046743224i | BG7: =20*LOG(IMABS(BF7)) -> 5.9867626 | BH7: =(180/PI())*IMARGUMENT(BF7) -> 42.069409 | BI7: =IMPRODUCT(AP7,BC7) -> 6.20411874335539+6.6127962853739i | BJ7: =20*LOG(IMABS(BI7)) -> 19.149783 | BK7: =(180/PI())*IMARGUMENT(BI7) -> 46.826303 | BL7: =IF($B$31=0,BJ7,BG7) -> 5.9867626 | BM7: =IF($B$31=0,BK7,BH7) -> 42.069409
N8: Fcross (VINvar) | O8: =fcross -> 1400 | P8: =COMPLEX(Adc,0) -> 16.5157725627975 | Q8: =IMSUM(COMPLEX(1,0),IMDIV(COMPLEX(0,2*PI()*O8),COMPLEX(wp_lf,0))) -> 1+22.760583984388i | R8: =IMABS(Q8) -> 22.782541 | S8: =IMARGUMENT(Q8) -> 1.526889 | T8: =IMSUM(COMPLEX(1,0),IMDIV(COMPLEX(0,2*PI()*O8),COMPLEX(wz_esr,0))) -> 1+0.144701757624346i | U8: =IMABS(T8) -> 1.0104151 | V8: =IMARGUMENT(T8) -> 0.14370431 | W8: =IMSUB(COMPLEX(1,0),IMDIV(COMPLEX(0,2*PI()*O8),COMPLEX(wz_rhp,0))) -> 1-2.19911485751286i | X8: =IMABS(W8) -> 2.4158034 | Y8: =IMARGUMENT(W8) -> -1.1440172 | Z8: =IMSUM(COMPLEX(1,0),IMDIV(COMPLEX(0,2*PI()*O8),COMPLEX(Q*(wsl/2),0)),IMDIV(IMPOWER(COMPLEX(0,2*PI()*O8),2),IMPOWER(COMPLEX(wsl/2,0),2))) -> 0.999959504132231+0.0307876080051799i | AA8: =IMABS(Z8) -> 1.0004333 | AB8: =IMARGUMENT(Z8) -> 0.030779132 | AC8: =(IMDIV(IMPRODUCT(P8,T8,W8),IMPRODUCT(Q8,Z8))) -> -1.47599479357241-0.974662318114615i | AD8: =20*LOG(IMABS(AC8)) -> 4.9533994 | AE8: =(180/PI())*IMARGUMENT(AC8) -> -146.56152 | AF8: =COMPLEX($B$72,0) -> 247.084651286898 | AG8: =IMSUM(COMPLEX(1,0),IMDIV(COMPLEX(0,2*PI()*O8),COMPLEX(wp_lf_DCM,0))) -> 1+22.2581659575986i | AH8: =IMABS(AG8) -> 22.280618 | AI8: =IMARGUMENT(AG8) -> 1.5258992 | AJ8: =IMSUM(COMPLEX(1,0),IMDIV(COMPLEX(0,2*PI()*O8),COMPLEX(wz1_dcm,0))) -> 1+0.144701757624346i | AK8: =IMABS(AJ8) -> 1.0104151 | AL8: =IMARGUMENT(AJ8) -> 0.14370431 | AM8: =IMSUB(COMPLEX(1,0),IMDIV(COMPLEX(0,2*PI()*O8),COMPLEX(wz2_dcm,0))) -> 1-0.143747565784003i | AN8: =IMABS(AM8) -> 1.0102789 | AO8: =IMARGUMENT(AM8) -> -0.14276956 | AP8: =(IMDIV(IMPRODUCT(AF8,AJ8,AM8),IMPRODUCT(AG8))) -> 0.518651096303595-11.3084560174839i | AQ8: =20*LOG(IMABS(AP8)) -> 21.077192 | AR8: =(180/PI())*IMARGUMENT(AP8) -> -87.374026 | AS8: =COMPLEX(Adc_ea,0) -> -0.0000166666666666667 | AT8: =COMPLEX(0,2*PI()*O8*wp0_ea) -> 0.0000299079620621748i | AU8: =IMABS(AT8) -> 2.9907962e-05 | AV8: =IMARGUMENT(AT8) -> 1.5707963 | AW8: =IMSUM(COMPLEX(1,0),IMDIV(COMPLEX(0,2*PI()*O8),COMPLEX(wp1_ea,0))) -> 1+0.0303943545247777i | AX8: =IMABS(AW8) -> 1.0004618 | AY8: =IMARGUMENT(AW8) -> 0.030385 | AZ8: =IMSUM(COMPLEX(1,0),IMDIV(COMPLEX(0,2*PI()*O8),COMPLEX(wz_ea,0))) -> 1+1.03340805384244i | BA8: =IMABS(AZ8) -> 1.4380307 | BB8: =IMARGUMENT(AZ8) -> 0.80182627 | BC8: =IMPRODUCT(AS8,IMDIV(AZ8,IMPRODUCT(AT8,AW8))) -> -0.55842875082386+0.574238288333766i | BD8: =20*LOG(IMABS(BC8)) -> -1.9274087 | BE8: =(180/PI())*IMARGUMENT(BC8) -> 134.20033 | BF8: =IMPRODUCT(AC8,BC8) -> 1.38392635005472-0.303293263070739i | BG8: =20*LOG(IMABS(BF8)) -> 3.0259907 | BH8: =(180/PI())*IMARGUMENT(BF8) -> -12.361186 | BI8: =IMPRODUCT(AP8,BC8) -> 6.20411874335539+6.6127962853739i | BJ8: =20*LOG(IMABS(BI8)) -> 19.149783 | BK8: =(180/PI())*IMARGUMENT(BI8) -> 46.826303 | BL8: =IF($B$31=0,BJ8,BG8) -> 3.0259907 | BM8: =IF($B$31=0,BK8,BH8) -> -12.361186
A9: Input Parameters | N9: wz_RHP | O9: =IF($B$31=0,B78,wz_rhp/(2*PI())) -> 636.61977 | P9: =COMPLEX(Adc,0) -> 16.5157725627975 | Q9: =IMSUM(COMPLEX(1,0),IMDIV(COMPLEX(0,2*PI()*O9),COMPLEX(wp_lf,0))) -> 1+10.3498841393531i | R9: =IMABS(Q9) -> 10.398082 | S9: =IMARGUMENT(Q9) -> 1.4744759 | T9: =IMSUM(COMPLEX(1,0),IMDIV(COMPLEX(0,2*PI()*O9),COMPLEX(wz_esr,0))) -> 1+0.0658i | U9: =IMABS(T9) -> 1.0021625 | V9: =IMARGUMENT(T9) -> 0.065705282 | W9: =IMSUB(COMPLEX(1,0),IMDIV(COMPLEX(0,2*PI()*O9),COMPLEX(wz_rhp,0))) -> 1-i | X9: =IMABS(W9) -> 1.4142136 | Y9: =IMARGUMENT(W9) -> -0.78539816 | Z9: =IMSUM(COMPLEX(1,0),IMDIV(COMPLEX(0,2*PI()*O9),COMPLEX(Q*(wsl/2),0)),IMDIV(IMPOWER(COMPLEX(0,2*PI()*O9),2),IMPOWER(COMPLEX(wsl/2,0),2))) -> 0.999991626348459+0.014i | AA9: =IMABS(Z9) -> 1.0000896 | AB9: =IMARGUMENT(Z9) -> 0.013999203 | AC9: =(IMDIV(IMPRODUCT(P9,T9,W9),IMPRODUCT(Q9,Z9))) -> -1.33948859332938-1.8089795848172i | AD9: =20*LOG(IMABS(AC9)) -> 7.0471978 | AE9: =(180/PI())*IMARGUMENT(AC9) -> -126.5187 | AF9: =COMPLEX($B$72,0) -> 247.084651286898 | AG9: =IMSUM(COMPLEX(1,0),IMDIV(COMPLEX(0,2*PI()*O9),COMPLEX(wp_lf_DCM,0))) -> 1+10.1214203894616i | AH9: =IMABS(AG9) -> 10.170701 | AI9: =IMARGUMENT(AG9) -> 1.4723156 | AJ9: =IMSUM(COMPLEX(1,0),IMDIV(COMPLEX(0,2*PI()*O9),COMPLEX(wz1_dcm,0))) -> 1+0.0658i | AK9: =IMABS(AJ9) -> 1.0021625 | AL9: =IMARGUMENT(AJ9) -> 0.065705282 | AM9: =IMSUB(COMPLEX(1,0),IMDIV(COMPLEX(0,2*PI()*O9),COMPLEX(wz2_dcm,0))) -> 1-0.0653661018627184i | AN9: =IMABS(AM9) -> 1.0021341 | AO9: =IMARGUMENT(AM9) -> -0.065273243 | AP9: =(IMDIV(IMPRODUCT(AF9,AJ9,AM9),IMPRODUCT(AG9))) -> 2.40936684475397-24.2790051382414i | AQ9: =20*LOG(IMABS(AP9)) -> 27.747177 | AR9: =(180/PI())*IMARGUMENT(AP9) -> -84.332715 | AS9: =COMPLEX(Adc_ea,0) -> -0.0000166666666666667 | AT9: =COMPLEX(0,2*PI()*O9*wp0_ea) -> 0.0000136i | AU9: =IMABS(AT9) -> 1.36e-05 | AV9: =IMARGUMENT(AT9) -> 1.5707963 | AW9: =IMSUM(COMPLEX(1,0),IMDIV(COMPLEX(0,2*PI()*O9),COMPLEX(wp1_ea,0))) -> 1+0.0138211764705882i | AX9: =IMABS(AW9) -> 1.0000955 | AY9: =IMARGUMENT(AW9) -> 0.013820297 | AZ9: =IMSUM(COMPLEX(1,0),IMDIV(COMPLEX(0,2*PI()*O9),COMPLEX(wz_ea,0))) -> 1+0.46992i | BA9: =IMABS(AZ9) -> 1.1049094 | BB9: =IMARGUMENT(AZ9) -> 0.43929536 | BC9: =IMPRODUCT(AS9,IMDIV(AZ9,IMPRODUCT(AT9,AW9))) -> -0.558837884716523+1.23321399310155i | BD9: =20*LOG(IMABS(BC9)) -> 2.6319007 | BE9: =(180/PI())*IMARGUMENT(BC9) -> 114.37793 | BF9: =IMPRODUCT(AC9,BC9) -> 2.9794159093297-0.640949752219085i | BG9: =20*LOG(IMABS(BF9)) -> 9.6790985 | BH9: =(180/PI())*IMARGUMENT(BF9) -> -12.140779 | BI9: =IMPRODUCT(AP9,BC9) -> 28.5947634040353+16.5392927819419i | BJ9: =20*LOG(IMABS(BI9)) -> 30.379078 | BK9: =(180/PI())*IMARGUMENT(BI9) -> 30.045211 | BL9: =IF($B$31=0,BJ9,BG9) -> 9.6790985 | BM9: =IF($B$31=0,BK9,BH9) -> -12.140779
A10: VIN_min | B10: =VIN_min -> 10 | C10: V | E10: Minimum input voltage | N10: wz_esr | O10: =IF(B31=0,B76,wz_esr/(2*PI())) -> 9675.0725 | P10: =COMPLEX(Adc,0) -> 16.5157725627975 | Q10: =IMSUM(COMPLEX(1,0),IMDIV(COMPLEX(0,2*PI()*O10),COMPLEX(wp_lf,0))) -> 1+157.293072026643i | R10: =IMABS(Q10) -> 157.29625 | S10: =IMARGUMENT(Q10) -> 1.5644389 | T10: =IMSUM(COMPLEX(1,0),IMDIV(COMPLEX(0,2*PI()*O10),COMPLEX(wz_esr,0))) -> 1+i | U10: =IMABS(T10) -> 1.4142136 | V10: =IMARGUMENT(T10) -> 0.78539816 | W10: =IMSUB(COMPLEX(1,0),IMDIV(COMPLEX(0,2*PI()*O10),COMPLEX(wz_rhp,0))) -> 1-15.1975683890577i | X10: =IMABS(W10) -> 15.230433 | Y10: =IMARGUMENT(W10) -> -1.505091 | Z10: =IMSUM(COMPLEX(1,0),IMDIV(COMPLEX(0,2*PI()*O10),COMPLEX(Q*(wsl/2),0)),IMDIV(IMPOWER(COMPLEX(0,2*PI()*O10),2),IMPOWER(COMPLEX(wsl/2,0),2))) -> 0.998065970486995+0.212765957446808i | AA10: =IMABS(Z10) -> 1.0204925 | AB10: =IMARGUMENT(Z10) -> 0.21003425 | AC10: =(IMDIV(IMPRODUCT(P10,T10,W10),IMPRODUCT(Q10,Z10))) -> -1.76768160054785-1.33663568098271i | AD10: =20*LOG(IMABS(AC10)) -> 6.9119586 | AE10: =(180/PI())*IMARGUMENT(AC10) -> -142.90518 | AF10: =COMPLEX($B$72,0) -> 247.084651286898 | AG10: =IMSUM(COMPLEX(1,0),IMDIV(COMPLEX(0,2*PI()*O10),COMPLEX(wp_lf_DCM,0))) -> 1+153.820978563247i | AH10: =IMABS(AG10) -> 153.82423 | AI10: =IMARGUMENT(AG10) -> 1.5642954 | AJ10: =IMSUM(COMPLEX(1,0),IMDIV(COMPLEX(0,2*PI()*O10),COMPLEX(wz1_dcm,0))) -> 1+i | AK10: =IMABS(AJ10) -> 1.4142136 | AL10: =IMARGUMENT(AJ10) -> 0.78539816 | AM10: =IMSUB(COMPLEX(1,0),IMDIV(COMPLEX(0,2*PI()*O10),COMPLEX(wz2_dcm,0))) -> 1-0.993405803384777i | AN10: =IMABS(AM10) -> 1.4095585 | AO10: =IMARGUMENT(AM10) -> -0.78209017 | AP10: =(IMDIV(IMPRODUCT(AF10,AJ10,AM10),IMPRODUCT(AG10))) -> 0.0314076432723136-3.20182965132306i | AQ10: =20*LOG(IMABS(AP10)) -> 10.108382 | AR10: =(180/PI())*IMARGUMENT(AP10) -> -89.437988 | AS10: =COMPLEX(Adc_ea,0) -> -0.0000166666666666667 | AT10: =COMPLEX(0,2*PI()*O10*wp0_ea) -> 0.000206686930091185i | AU10: =IMABS(AT10) -> 0.00020668693 | AV10: =IMARGUMENT(AT10) -> 1.5707963 | AW10: =IMSUM(COMPLEX(1,0),IMDIV(COMPLEX(0,2*PI()*O10),COMPLEX(wp1_ea,0))) -> 1+0.210048274629i | AX10: =IMABS(AW10) -> 1.021822 | AY10: =IMARGUMENT(AW10) -> 0.20703843 | AZ10: =IMSUM(COMPLEX(1,0),IMDIV(COMPLEX(0,2*PI()*O10),COMPLEX(wz_ea,0))) -> 1+7.14164133738602i | BA10: =IMABS(AZ10) -> 7.2113134 | BB10: =IMARGUMENT(AZ10) -> 1.431677 | BC10: =IMPRODUCT(AS10,IMDIV(AZ10,IMPRODUCT(AT10,AW10))) -> -0.535325908929803+0.193081538436867i | BD10: =20*LOG(IMABS(BC10)) -> -4.8965032 | BE10: =(180/PI())*IMARGUMENT(BC10) -> 160.16662 | BF10: =IMPRODUCT(AC10,BC10) -> 1.20436543312552+0.374229027929753i | BG10: =20*LOG(IMABS(BF10)) -> 2.0154554 | BH10: =(180/PI())*IMARGUMENT(BF10) -> 17.261438 | BI10: =IMPRODUCT(AP10,BC10) -> 0.60140086970814+1.72008660441461i | BJ10: =20*LOG(IMABS(BI10)) -> 5.2118791 | BK10: =(180/PI())*IMARGUMENT(BI10) -> 70.728634 | BL10: =IF($B$31=0,BJ10,BG10) -> 2.0154554 | BM10: =IF($B$31=0,BK10,BH10) -> 17.261438
A11: VIN_nom | B11: =VIN_nom -> 3 | C11: V | E11: Nominal input voltage | N11: wp_lf | O11: =IF(B31=0,B74,wp_lf/(2*PI())) -> 61.509845 | P11: =COMPLEX(Adc,0) -> 16.5157725627975 | Q11: =IMSUM(COMPLEX(1,0),IMDIV(COMPLEX(0,2*PI()*O11),COMPLEX(wp_lf,0))) -> 1+i | R11: =IMABS(Q11) -> 1.4142136 | S11: =IMARGUMENT(Q11) -> 0.78539816 | T11: =IMSUM(COMPLEX(1,0),IMDIV(COMPLEX(0,2*PI()*O11),COMPLEX(wz_esr,0))) -> 1+0.00635755909090909i | U11: =IMABS(T11) -> 1.0000202 | V11: =IMARGUMENT(T11) -> 0.0063574734 | W11: =IMSUB(COMPLEX(1,0),IMDIV(COMPLEX(0,2*PI()*O11),COMPLEX(wz_rhp,0))) -> 1-0.0966194390715667i | X11: =IMABS(W11) -> 1.0046568 | Y11: =IMARGUMENT(W11) -> -0.096320454 | Z11: =IMSUM(COMPLEX(1,0),IMDIV(COMPLEX(0,2*PI()*O11),COMPLEX(Q*(wsl/2),0)),IMDIV(IMPOWER(COMPLEX(0,2*PI()*O11),2),IMPOWER(COMPLEX(wsl/2,0),2))) -> 0.999999921829317+0.00135267214700193i | AA11: =IMABS(Z11) -> 1.0000008 | AB11: =IMARGUMENT(Z11) -> 0.0013526714 | AC11: =(IMDIV(IMPRODUCT(P11,T11,W11),IMPRODUCT(Q11,Z11))) -> 7.50538799587183-9.01848417665106i | AD11: =20*LOG(IMABS(AC11)) -> 21.388201 | AE11: =(180/PI())*IMARGUMENT(AC11) -> -50.232001 | AF11: =COMPLEX($B$72,0) -> 247.084651286898 | AG11: =IMSUM(COMPLEX(1,0),IMDIV(COMPLEX(0,2*PI()*O11),COMPLEX(wp_lf_DCM,0))) -> 1+0.9779259606373i | AH11: =IMABS(AG11) -> 1.398692 | AI11: =IMARGUMENT(AG11) -> 0.77423843 | AJ11: =IMSUM(COMPLEX(1,0),IMDIV(COMPLEX(0,2*PI()*O11),COMPLEX(wz1_dcm,0))) -> 1+0.00635755909090909i | AK11: =IMABS(AJ11) -> 1.0000202 | AL11: =IMARGUMENT(AJ11) -> 0.0063574734 | AM11: =IMSUB(COMPLEX(1,0),IMDIV(COMPLEX(0,2*PI()*O11),COMPLEX(wz2_dcm,0))) -> 1-0.00631563609627074i | AN11: =IMABS(AM11) -> 1.0000199 | AO11: =IMARGUMENT(AM11) -> -0.0063155521 | AP11: =(IMDIV(IMPRODUCT(AF11,AJ11,AM11),IMPRODUCT(AG11))) -> 126.309744276638-123.511219481072i | AQ11: =20*LOG(IMABS(AP11)) -> 44.942823 | AR11: =(180/PI())*IMARGUMENT(AP11) -> -44.358193 | AS11: =COMPLEX(Adc_ea,0) -> -0.0000166666666666667 | AT11: =COMPLEX(0,2*PI()*O11*wp0_ea) -> 1.31402437137331E-06i | AU11: =IMABS(AT11) -> 1.3140244e-06 | AV11: =IMARGUMENT(AT11) -> 1.5707963 | AW11: =IMSUM(COMPLEX(1,0),IMDIV(COMPLEX(0,2*PI()*O11),COMPLEX(wp1_ea,0))) -> 1+0.00133539431789737i | AX11: =IMABS(AW11) -> 1.0000009 | AY11: =IMARGUMENT(AW11) -> 0.0013353935 | AZ11: =IMSUM(COMPLEX(1,0),IMDIV(COMPLEX(0,2*PI()*O11),COMPLEX(wz_ea,0))) -> 1+0.0454034068085106i | BA11: =IMABS(AZ11) -> 1.0010302 | BB11: =IMARGUMENT(AZ11) -> 0.045372246 | BC11: =IMPRODUCT(AS11,IMDIV(AZ11,IMPRODUCT(AT11,AW11))) -> -0.558943639926313+12.6844279534856i | BD11: =20*LOG(IMABS(BC11)) -> 22.073842 | BE11: =(180/PI())*IMARGUMENT(BC11) -> 92.523126 | BF11: =IMPRODUCT(AC11,BC11) -> 110.199223902908+100.242377668907i | BG11: =20*LOG(IMABS(BF11)) -> 43.462043 | BH11: =(180/PI())*IMARGUMENT(BF11) -> 42.291124 | BI11: =IMPRODUCT(AP11,BC11) -> 1496.06913673066+1671.20266168869i | BJ11: =20*LOG(IMABS(BI11)) -> 67.016665 | BK11: =(180/PI())*IMARGUMENT(BI11) -> 48.164933 | BL11: =IF($B$31=0,BJ11,BG11) -> 43.462043 | BM11: =IF($B$31=0,BK11,BH11) -> 42.291124
